Workbook

Sheet REGISTRO  1- lote 9
B1: AVICOLA SAN LORENZO
B2: GRANJA : | E2: SAN LORENZO
B3: RESPONSABLE : | O3: MACHO
B5: GALPON | D5: LOTE | G5: INCUBADORA | K5: CANTIDAD INICIAL | O5: PESO PROMEDIO INIC.
B6: T1 | D6: 49 | G6: FINAVES | K6: 6578 | O6: 44
B8: FECHA INICIO | G8: 45780 | L8: DIAS DE ENGORDE: | P8: =(G9-G8)+1 -> 49
B9: FECHA TERMINACION | G9: =+PESAS!B11 -> 45828 | L9: DIAS PROMEDIO
B11: POLLOS VENDIDOS | Z11: conversion: kilos concentrado/ kilos en pie
B12: PESO TOTAL FINAL | L12: CONSUMO TOTAL DEL LOTE | Z12: se necesita xxx kilos concentrado para producir 1 kilo de pollo en pie
Z13: Entre mas bajo mejor
I14: TOTAL CONSUMO | Q14: CONSUMO POR AVE | U14: PESO
A15: KILOS CONSUMIDOS | I15: SEMANAL | M15: ACUMULADO | Q15: (Gramos) | T15: CONSUMO | U15: GRAMOS | V15: gramos | Z15: BULTOS CONSUMIDOS
A16: S/D | B16: S | C16: D | D16: L | E16: M | F16: M | G16: J | H16: V | I16: Bultos | K16: Kilos | M16: Bultos | O16: Kilos | Q16: Diario | R16: Sem. | S16: Acumul. | T16: KL. | U16: PROMEDIO | V16: Ganancia dia | W16: Conversion | X16: VPI | Z16: S/D | AA16: S | AB16: D | AC16: L | AD16: M | AE16: M | AF16: J | AG16: V | AH16: TOTAL | AL16: BULTOS CONSUMIDOS
A17: 1 | B17: =+AA17*40 -> 80 | C17: =+AB17*40 -> 80 | D17: =+AC17*40 -> 120 | E17: =+AD17*40 -> 160 | F17: =+AE17*40 -> 160 | G17: =+AF17*40 -> 200 | H17: =+AG17*40 -> 240 | I17: =+K17/40 -> 26 | K17: =SUM(B17:H17) -> 1040 | M17: =+I17 -> 26 | O17: =+K17 -> 1040 | Q17: =+R17/7 -> 23.020054 | R17: =+K17*1000/S30 -> 161.14038 | S17: =+R17 -> 161.14038 | T17: =+O17/S30 -> 0.16114038 | U17: 195 | V17: =(U17-O6)/7 -> 21.571429 | W17: =+O17/(S30*(U17/1000)) -> 0.82636091 | X17: =+U17/O6 -> 4.4318182 | Z17: 1 | AA17: 2 | AB17: 2 | AC17: 3 | AD17: 4 | AE17: 4 | AF17: 5 | AG17: 6 | AH17: =+SUM(AA17:AG17) -> 26 | AL17: S/D | AM17: S | AN17: D | AO17: L | AP17: M | AQ17: M | AR17: J | AS17: V | AT17: TOTAL
A18: 2 | B18: =+AA18*40 -> 240 | C18: =+AB18*40 -> 240 | D18: =+AC18*40 -> 280 | E18: =+AD18*40 -> 320 | F18: =+AE18*40 -> 360 | G18: =+AF18*40 -> 380 | H18: =+AG18*40 -> 400 | I18: =+K18/40 -> 55.5 | K18: =SUM(B18:H18) -> 2220 | M18: =+M17+I18 -> 81.5 | O18: =+O17+K18 -> 3260 | Q18: =+R18/7 -> 49.576811 | R18: =+K18*1000/S31 -> 347.03767 | S18: =+O18*1000/S31 -> 509.61388 | T18: =+O18/S31 -> 0.50961388 | U18: 455 | V18: =+(U18-U17)/7 -> 37.142857 | W18: =+O18/(S31*(U18/1000)) -> 1.1200305 | X18: =+U18/U17 -> 2.3333333 | Z18: 2 | AA18: 6 | AB18: 6 | AC18: 7 | AD18: 8 | AE18: 9 | AF18: 9.5 | AG18: 10 | AH18: =+SUM(AA18:AG18) -> 55.5 | AL18: 1 | AM18: 3 | AN18: 1 | AO18: 2 | AP18: 2 | AQ18: 2 | AR18: 2.5 | AS18: 2 | AT18: =+SUM(AM18:AS18) -> 14.5 | AU18: 3742
A19: 3 | B19: =+AA19*40 -> 400 | C19: =+AB19*40 -> 440 | D19: =+AC19*40 -> 480 | E19: =+AD19*40 -> 520 | F19: =+AE19*40 -> 560 | G19: =+AF19*40 -> 600 | H19: =+AG19*40 -> 600 | I19: =+K19/40 -> 90 | K19: =SUM(B19:H19) -> 3600 | M19: =+M18+I19 -> 171.5 | O19: =+O18+K19 -> 6860 | Q19: =+R19/7 -> 80.938891 | R19: =+K19*1000/S32 -> 566.57224 | S19: =+O19*1000/S32 -> 1079.6349 | T19: =+O19/S32 -> 1.0796349 | U19: 880 | V19: =+(U19-U18)/7 -> 60.714286 | W19: =+O19/(S32*(U19/1000)) -> 1.2268578 | X19: =+U19/U18 -> 1.9340659 | Z19: 3 | AA19: 10 | AB19: 11 | AC19: 12 | AD19: 13 | AE19: 14 | AF19: 15 | AG19: 15 | AH19: =+SUM(AA19:AG19) -> 90 | AL19: 2 | AM19: 3 | AN19: 3.5 | AO19: 4 | AP19: 5 | AQ19: 5 | AR19: 6 | AS19: 6 | AT19: =+SUM(AM19:AS19) -> 32.5
A20: 4 | B20: =+AA20*40 -> 680 | C20: =+AB20*40 -> 720 | D20: =+AC20*40 -> 760 | E20: =+AD20*40 -> 800 | F20: =+AE20*40 -> 840 | G20: =+AF20*40 -> 880 | H20: =+AG20*40 -> 880 | I20: =+K20/40 -> 139 | K20: =SUM(B20:H20) -> 5560 | M20: =+M19+I20 -> 310.5 | O20: =+O19+K20 -> 12420 | Q20: =+R20/7 -> 125.55892 | R20: =+K20*1000/S33 -> 878.91242 | S20: =+O20*1000/S33 -> 1963.326 | T20: =+O20/S33 -> 1.963326 | U20: 1450 | V20: =+(U20-U19)/7 -> 81.428571 | W20: =+O20/(S33*(U20/1000)) -> 1.3540179 | X20: =+U20/U19 -> 1.6477273 | Z20: 4 | AA20: 17 | AB20: 18 | AC20: 19 | AD20: 20 | AE20: 21 | AF20: 22 | AG20: 22 | AH20: =+SUM(AA20:AG20) -> 139 | AL20: 3 | AM20: 6 | AN20: 6 | AO20: 7 | AP20: 8 | AQ20: 8 | AR20: 9 | AS20: 9 | AT20: =+SUM(AM20:AS20) -> 53
A21: 5 | B21: =+AA21*40 -> 920 | C21: =+AB21*40 -> 920 | D21: =+AC21*40 -> 960 | E21: =+AD21*40 -> 1000 | F21: =+AE21*40 -> 1000 | G21: =+AF21*40 -> 1040 | H21: =+AG21*40 -> 1040 | I21: =+K21/40 -> 172 | K21: =SUM(B21:H21) -> 6880 | M21: =+M20+I21 -> 482.5 | O21: =+O20+K21 -> 19300 | Q21: =+R21/7 -> 156.90567 | R21: =+K21*1000/S34 -> 1098.3397 | S21: =+O21*1000/S34 -> 3081.0983 | T21: =+O21/S34 -> 3.0810983 | U21: 2050 | V21: =+(U21-U20)/7 -> 85.714286 | W21: =+O21/(S34*(U21/1000)) -> 1.5029748 | X21: =+U21/U20 -> 1.4137931 | Z21: 5 | AA21: 23 | AB21: 23 | AC21: 24 | AD21: 25 | AE21: 25 | AF21: 26 | AG21: 26 | AH21: =+SUM(AA21:AG21) -> 172 | AL21: 4 | AM21: 10 | AN21: 10 | AO21: 11 | AP21: 11 | AQ21: 12 | AR21: 12 | AS21: 13 | AT21: =+SUM(AM21:AS21) -> 79
A22: 6 | B22: =+AA22*40 -> 1040 | C22: =+AB22*40 -> 1040 | D22: =+AC22*40 -> 1040 | E22: =+AD22*40 -> 1040 | F22: =+AE22*40 -> 1080 | G22: =+AF22*40 -> 1080 | H22: =+AG22*40 -> 1040 | I22: =+K22/40 -> 184 | K22: =SUM(B22:H22) -> 7360 | M22: =+M21+I22 -> 666.5 | O22: =+O21+K22 -> 26660 | Q22: =+R22/7 -> 169.394 | R22: =+K22*1000/S35 -> 1185.758 | S22: =+O22*1000/S35 -> 4295.1506 | T22: =+O22/S35 -> 4.2951506 | U22: 2680 | V22: =+(U22-U21)/7 -> 90 | W22: =+O22/(S35*(U22/1000)) -> 1.6026681 | X22: =+U22/U21 -> 1.3073171 | Z22: 6 | AA22: 26 | AB22: 26 | AC22: 26 | AD22: 26 | AE22: 27 | AF22: 27 | AG22: 26 | AH22: =+SUM(AA22:AG22) -> 184 | AL22: 5 | AM22: 13 | AN22: 13 | AO22: 13 | AP22: 13 | AQ22: 13 | AR22: 13 | AS22: 13 | AT22: =+SUM(AM22:AS22) -> 91
A23: 7 | B23: =+AA23*40 -> 1040 | C23: =+AB23*40 -> 1040 | D23: =+AC23*40 -> 1000 | E23: =+AD23*40 -> 1000 | F23: =+AE23*40 -> 800 | G23: =+AF23*40 -> 720 | H23: =+AG23*40 -> 0 | I23: =+K23/40 -> 140 | K23: =SUM(B23:H23) -> 5600 | M23: =+M22+I23 -> 806.5 | O23: =+O22+K23 -> 32260 | Q23: =+R23/7 -> 129.87013 | R23: =+K23*1000/S36 -> 909.09091 | S23: =+O23*1000/S36 -> 5237.013 | T23: =+O23/S36 -> 5.237013 | V23: =+(U23-U22)/7 -> -382.85714 | W23: =+O23/(S36*(U23/1000)) -> #DIV/0! | X23: =+U23/U22 -> 0 | Z23: 7 | AA23: 26 | AB23: 26 | AC23: 25 | AD23: 25 | AE23: 20 | AF23: 18 | AH23: =+SUM(AA23:AG23) -> 140 | AL23: 6 | AM23: 15 | AN23: 15 | AO23: 15 | AP23: 15 | AQ23: 15 | AR23: 15 | AS23: 15 | AT23: =+SUM(AM23:AS23) -> 105
A24: 8 | B24: =+AA24*40 -> 0 | C24: =+AB24*40 -> 0 | D24: =+AC24*40 -> 0 | E24: =+AD24*40 -> 0 | F24: =+AE24*40 -> 0 | G24: =+AF24*40 -> 0 | H24: =+AG24*40 -> 0 | I24: =+K24/40 -> 0 | K24: =SUM(B24:H24) -> 0 | M24: =+M23+I24 -> 806.5 | O24: =+O23+K24 -> 32260 | Q24: =+R24/7 -> 0 | R24: =+K24*1000/S37 -> 0 | S24: =+O24*1000/S37 -> 5237.013 | T24: =+O24/S37 -> 5.237013 | V24: =+(U24-U23)/7 -> 0 | W24: =+O24/(S37*(U24/1000)) -> #DIV/0! | X24: =+U24/U23 -> #DIV/0! | Z24: 8 | AH24: =+SUM(AA24:AG24) -> 0 | AL24: 7 | AM24: 15 | AN24: 15 | AO24: 15 | AP24: 15 | AQ24: 15 | AT24: =+SUM(AM24:AS24) -> 75
A25: 9 | B25: =+AA25*40 -> 0 | C25: =+AB25*40 -> 0 | D25: =+AC25*40 -> 0 | E25: =+AD25*40 -> 0 | F25: =+AE25*40 -> 0 | G25: =+AF25*40 -> 0 | H25: =+AG25*40 -> 0 | I25: =+K25/40 -> 0 | K25: =SUM(B25:H25) -> 0 | M25: =+M24+I25 -> 806.5 | O25: =+O24+K25 -> 32260 | Q25: =+R25/7 -> 0 | R25: =+K25*1000/S38 -> 0 | S25: =+O25*1000/S38 -> 5237.013 | T25: =+O25/S38 -> 5.237013 | V25: =+(U25-U24)/7 -> 0 | W25: =+O25/(S38*(U25/1000)) -> #DIV/0! | X25: =+U25/U24 -> #DIV/0! | Z25: 9 | AH25: =+SUM(AA25:AG25) -> 0 | AL25: 8 | AT25: =+SUM(AM25:AS25) -> 0
AL26: 9 | AT26: =+SUM(AM26:AS26) -> 0 | AV26: =3+1+2+2.5+2+2.5+2.5 -> 15.5
I27: TOTAL MORTALIDAD Y SELECCIÓN | S27: SALDO | AT27: =+SUM(AT18:AT26) -> 450 | AU27: =454+0.5+2.5+1-8 -> 450 | AV27: =481+2.5+1+-8 -> 476.5
B28: AVES MUERTAS POR DIA | I28: Mort./sem. | K28: Selec/Sem | M28: Mort.Acum. | O28: Selec.Acum. | Q28: Mort/Selec.Ac. | S28: AVES | AV28: =481+2.5+1-8 -> 476.5
A29: S/D | B29: =+B16 -> S | C29: =+C16 -> D | D29: =+D16 -> L | E29: =+E16 -> M | F29: =+F16 -> M | G29: =+G16 -> J | H29: =+H16 -> V | I29: No.A. | J29: % | K29: No.A. | L29: % | M29: No.A. | N29: % | O29: No.A. | P29: % | Q29: No.A. | R29: % | S29: (superv.) | AL29: BULTOS CONSUMIDOS | AV29: =3+1+2+2+2+2.5+2 -> 14.5
A30: 1 | B30: =3+6 -> 9 | C30: =2+4 -> 6 | D30: =4+6 -> 10 | E30: =10+14 -> 24 | F30: =16+15 -> 31 | G30: =8+12 -> 20 | H30: =10+14 -> 24 | I30: =SUM(B30:H30) -> 124 | J30: =+I30/K6 -> 0.018850715 | M30: =+I30 -> 124 | N30: =+M30/K$6 -> 0.018850715 | Q30: =+M30+O30 -> 124 | R30: =+Q30/$K$6 -> 0.018850715 | S30: =+K6-I30-K30 -> 6454 | AL30: S/D | AM30: =+'[1]REGISTRO 1 LOTE 9'!M29 -> No.A. | AN30: =+'[1]REGISTRO 1 LOTE 9'!N29 -> % | AO30: =+'[1]REGISTRO 1 LOTE 9'!O29 -> No.A. | AP30: =+'[1]REGISTRO 1 LOTE 9'!P29 -> % | AQ30: =+'[1]REGISTRO 1 LOTE 9'!Q29 -> No.A. | AR30: =+'[1]REGISTRO 1 LOTE 9'!R29 -> % | AS30: =+'[1]REGISTRO 1 LOTE 9'!S29 -> (superv.) | AT30: TOTAL | AV30: =439+0.5+2.5+1+-8 -> 435
A31: 2 | B31: 4 | C31: 6 | D31: 7 | E31: 7 | F31: 9 | G31: 10 | H31: 14 | I31: =SUM(B31:H31) -> 57 | J31: =+I31/S30 -> 0.0088317323 | M31: =+M30+I31 -> 181 | N31: =+M31/K$6 -> 0.027515962 | Q31: =+M31+O31 -> 181 | R31: =+Q31/$K$6 -> 0.027515962 | S31: =+S30-I31-K31 -> 6397 | AL31: 1 | AM31: 3 | AN31: 1 | AO31: 2 | AP31: 2.5 | AQ31: 2 | AR31: 2.5 | AS31: 2.5 | AT31: =+SUM(AM31:AS31) -> 15.5 | AU31: 3742
A32: 3 | B32: 5 | C32: 7 | D32: 6 | E32: 8 | F32: 4 | G32: 6 | H32: 7 | I32: =SUM(B32:H32) -> 43 | J32: =+I32/S31 -> 0.0067219009 | M32: =+M31+I32 -> 224 | N32: =+M32/K$6 -> 0.034052904 | Q32: =+M32+O32 -> 224 | R32: =+Q32/$K$6 -> 0.034052904 | S32: =+S31-I32-K32 -> 6354 | AL32: 2 | AM32: 3 | AN32: 3.5 | AO32: 4 | AP32: 5 | AQ32: 5 | AR32: 6 | AS32: 6 | AT32: =+SUM(AM32:AS32) -> 32.5
A33: 4 | B33: 3 | C33: 4 | D33: 6 | E33: 3 | F33: 5 | G33: 4 | H33: 3 | I33: =SUM(B33:H33) -> 28 | J33: =+I33/S32 -> 0.004406673 | M33: =+M32+I33 -> 252 | N33: =+M33/K$6 -> 0.038309517 | Q33: =+M33+O33 -> 252 | R33: =+Q33/$K$6 -> 0.038309517 | S33: =+S32-I33-K33 -> 6326 | AL33: 3 | AM33: 6 | AN33: 6 | AO33: 7 | AP33: 8 | AQ33: 8 | AR33: 9 | AS33: 9 | AT33: =+SUM(AM33:AS33) -> 53
A34: 5 | B34: 9 | C34: 7 | D34: 8 | E34: 10 | F34: 9 | G34: 10 | H34: 9 | I34: =SUM(B34:H34) -> 62 | J34: =+I34/S33 -> 0.009800822 | M34: =+M33+I34 -> 314 | N34: =+M34/K$6 -> 0.047734874 | Q34: =+M34+O34 -> 314 | R34: =+Q34/$K$6 -> 0.047734874 | S34: =+S33-I34-K34 -> 6264 | AL34: 4 | AM34: 10 | AN34: 10 | AO34: 11 | AP34: 11 | AQ34: 12 | AR34: 12 | AS34: 13 | AT34: =+SUM(AM34:AS34) -> 79
A35: 6 | B35: 9 | C35: 6 | D35: 10 | E35: 8 | F35: 7 | G35: 8 | H35: 9 | I35: =SUM(B35:H35) -> 57 | J35: =+I35/S34 -> 0.0090996169 | M35: =+M34+I35 -> 371 | N35: =+M35/K$6 -> 0.056400122 | Q35: =+M35+O35 -> 371 | R35: =+Q35/$K$6 -> 0.056400122 | S35: =+S34-I35-K35 -> 6207 | AL35: 5 | AM35: 13 | AN35: 13 | AO35: 13 | AP35: 13 | AQ35: 13 | AR35: 13 | AS35: 13 | AT35: =+SUM(AM35:AS35) -> 91
A36: 7 | B36: 7 | C36: 8 | D36: 7 | E36: 9 | F36: 6 | G36: 4 | H36: 6 | I36: =SUM(B36:H36) -> 47 | J36: =+I36/S35 -> 0.007572096 | M36: =+M35+I36 -> 418 | N36: =+M36/K$6 -> 0.063545151 | Q36: =+M36+O36 -> 418 | R36: =+Q36/$K$6 -> 0.063545151 | S36: =+S35-I36-K36 -> 6160 | AL36: 6 | AM36: 15 | AN36: 15 | AO36: 15 | AP36: 15 | AQ36: 15 | AR36: 15 | AS36: 15 | AT36: =+SUM(AM36:AS36) -> 105
A37: 8 | I37: =SUM(B37:H37) -> 0 | J37: =+I37/S36 -> 0 | M37: =+M36+I37 -> 418 | N37: =+M37/K$6 -> 0.063545151 | Q37: =+M37+O37 -> 418 | R37: =+Q37/$K$6 -> 0.063545151 | S37: =+S36-I37-K37 -> 6160 | AL37: 7 | AM37: 15 | AN37: 15 | AO37: 15 | AP37: 15 | AQ37: 17 | AR37: 25 | AT37: =+SUM(AM37:AS37) -> 102 | AW37: =14+30+52+79+99+105+102 -> 481
A38: 9 | I38: =SUM(B38:H38) -> 0 | J38: =+I38/S37 -> 0 | M38: =+M37+I38 -> 418 | N38: =+M38/K$6 -> 0.063545151 | Q38: =+M38+O38 -> 418 | R38: =+Q38/$K$6 -> 0.063545151 | S38: =+S37-I38-K38 -> 6160 | AL38: 8 | AT38: =+SUM(AM38:AS38) -> 0
AL39: 9 | AT39: =+SUM(AM39:AS39) -> 0
B40: PESO POR AVE | E40: Aumento | G40: Conversion | I40: PROGRAMA DE VACUNACION | O40: TRATAMIENTO | AT40: =+SUM(AT31:AT39) -> 478 | AU40: =481+1.5+2.5+1-8 -> 478
A41: S/D | B41: Mach | C41: Hemb. | D41: Prom. | E41: por ave/dia | G41: alimento | I41: DIA | J41: MES | K41: VACUNA | O41: DIA | P41: MES | Q41: DROGA / DOSIS
A42: 1 | D42: =+(B42+C42)/2 -> 0 | E42: =+D42/7 -> 0 | G42: =+S17/D42 -> #DIV/0! | AL42: BULTOS CONSUMIDOS
A43: 2 | D43: =+(B43+C43)/2 -> 0 | E43: =(D43-D42)/7 -> 0 | G43: =+S18/D43 -> #DIV/0! | AL43: S/D | AM43: =+'[1]REGISTRO 1 LOTE 9'!M42 -> 0 | AN43: =+'[1]REGISTRO 1 LOTE 9'!N42 -> 0 | AO43: =+'[1]REGISTRO 1 LOTE 9'!O42 -> 0 | AP43: =+'[1]REGISTRO 1 LOTE 9'!P42 -> 0 | AQ43: =+'[1]REGISTRO 1 LOTE 9'!Q42 -> 0 | AR43: =+'[1]REGISTRO 1 LOTE 9'!R42 -> 0 | AS43: =+'[1]REGISTRO 1 LOTE 9'!S42 -> 0 | AT43: TOTAL
...

Sheet CONSUMO DIARIO 1
A1: GRANJA | B1: =+'REGISTRO 1- lote 9'!E2 -> SAN LORENZO
A2: GALPON: | B2: =+'REGISTRO 1- lote 9'!B6 -> T1 | C2: MACHOS | O2: HEMBRAS
A3: LOTE | B3: =+'REGISTRO 1- lote 9'!D6 -> 49
G4: CONSUMO DIARIO | S4: CONSUMO DIARIO
A5: FECHA | B5: SEMANA | C5: DIA | D5: MORTALIDAD | E5: SALIDA A PROCESO | F5: SALDO POLLITOS | G5: TOTAL KL | H5: X POLLO GR | I5: Acumul X P (gr) | J5: Peso pollito gr | K5: ganancia peso gr semanal | L5: Promedio ganancia peso gr dia | M5: CONVERSION | O5: DIA | P5: MORTALIDAD | Q5: SALIDA A PROCESO | R5: SALDO POLLITOS | S5: TOTAL KL | T5: X POLLO GR | U5: Acumul X P (gr) | V5: Peso pollito gr | W5: ganancia peso gr semanal | X5: Promedio ganancia peso gr dia | Y5: CONVERSION
A6: =+'REGISTRO 1- lote 9'!G8 -> 45780 | B6: Semana 1 | C6: 0 | F6: =+'REGISTRO 1- lote 9'!K6 -> 6578 | J6: =+'REGISTRO 1- lote 9'!O6 -> 44 | O6: 0 | R6: =+'REGISTRO 1- lote 9'!K57 -> 6018 | V6: =+'REGISTRO 1- lote 9'!O57 -> 44
A7: =+A6+1 -> 45781 | C7: 1 | D7: =+'REGISTRO 1- lote 9'!$B$30 -> 9 | F7: =+F6-D7-E7 -> 6569 | G7: =+'REGISTRO 1- lote 9'!$B$17 -> 80 | H7: =+G7*1000/F7 -> 12.178414 | I7: =+H7 -> 12.178414 | O7: 1 | P7: =+'REGISTRO 1- lote 9'!$B$81 -> 8 | R7: =+R6-P7-Q7 -> 6010 | S7: =+'REGISTRO 1- lote 9'!$B$68 -> 100 | T7: =+S7*1000/R7 -> 16.638935 | U7: =+T7 -> 16.638935
A8: =+A7+1 -> 45782 | C8: =+C7+1 -> 2 | D8: =+'REGISTRO 1- lote 9'!$C$30 -> 6 | F8: =+F7-D8-E8 -> 6563 | G8: =+'REGISTRO 1- lote 9'!$C$17 -> 80 | H8: =+G8*1000/F8 -> 12.189547 | I8: =+I7+H8 -> 24.367961 | O8: =+O7+1 -> 2 | P8: =+'REGISTRO 1- lote 9'!$C$81 -> 9 | R8: =+R7-P8-Q8 -> 6001 | S8: =+'REGISTRO 1- lote 9'!$C$68 -> 120 | T8: =+S8*1000/R8 -> 19.996667 | U8: =+U7+T8 -> 36.635602
A9: =+A8+1 -> 45783 | C9: =+C8+1 -> 3 | D9: =+'REGISTRO 1- lote 9'!$D$30 -> 10 | F9: =+F8-D9-E9 -> 6553 | G9: =+'REGISTRO 1- lote 9'!$D$17 -> 120 | H9: =+G9*1000/F9 -> 18.312223 | I9: =+I8+H9 -> 42.680185 | O9: =+O8+1 -> 3 | P9: =+'REGISTRO 1- lote 9'!$D$81 -> 8 | R9: =+R8-P9-Q9 -> 5993 | S9: =+'REGISTRO 1- lote 9'!$D$68 -> 120 | T9: =+S9*1000/R9 -> 20.023361 | U9: =+U8+T9 -> 56.658963
A10: =+A9+1 -> 45784 | C10: =+C9+1 -> 4 | D10: =+'REGISTRO 1- lote 9'!$E$30 -> 24 | F10: =+F9-D10-E10 -> 6529 | G10: =+'REGISTRO 1- lote 9'!$E$17 -> 160 | H10: =+G10*1000/F10 -> 24.50605 | I10: =+I9+H10 -> 67.186235 | O10: =+O9+1 -> 4 | P10: =+'REGISTRO 1- lote 9'!$E$81 -> 25 | R10: =+R9-P10-Q10 -> 5968 | S10: =+'REGISTRO 1- lote 9'!$E$68 -> 140 | T10: =+S10*1000/R10 -> 23.458445 | U10: =+U9+T10 -> 80.117408
A11: =+A10+1 -> 45785 | C11: =+C10+1 -> 5 | D11: =+'REGISTRO 1- lote 9'!$F$30 -> 31 | F11: =+F10-D11-E11 -> 6498 | G11: =+'REGISTRO 1- lote 9'!$F$17 -> 160 | H11: =+G11*1000/F11 -> 24.622961 | I11: =+I10+H11 -> 91.809195 | O11: =+O10+1 -> 5 | P11: =+'REGISTRO 1- lote 9'!$F$81 -> 16 | R11: =+R10-P11-Q11 -> 5952 | S11: =+'REGISTRO 1- lote 9'!$F$68 -> 160 | T11: =+S11*1000/R11 -> 26.88172 | U11: =+U10+T11 -> 106.99913
A12: =+A11+1 -> 45786 | C12: =+C11+1 -> 6 | D12: =+'REGISTRO 1- lote 9'!$G$30 -> 20 | F12: =+F11-D12-E12 -> 6478 | G12: =+'REGISTRO 1- lote 9'!$G$17 -> 200 | H12: =+G12*1000/F12 -> 30.873726 | I12: =+I11+H12 -> 122.68292 | O12: =+O11+1 -> 6 | P12: =+'REGISTRO 1- lote 9'!$G$81 -> 12 | R12: =+R11-P12-Q12 -> 5940 | S12: =+'REGISTRO 1- lote 9'!$G$68 -> 160 | T12: =+S12*1000/R12 -> 26.936027 | U12: =+U11+T12 -> 133.93516
A13: =+A12+1 -> 45787 | C13: =+C12+1 -> 7 | D13: =+'REGISTRO 1- lote 9'!$H$30 -> 24 | F13: =+F12-D13-E13 -> 6454 | G13: =+'REGISTRO 1- lote 9'!$H$17 -> 240 | H13: =+G13*1000/F13 -> 37.186241 | I13: =+I12+H13 -> 159.86916 | J13: =+'REGISTRO 1- lote 9'!U17 -> 195 | K13: =+J13-J6 -> 151 | L13: =+(J13-$J$6)/C13 -> 21.571429 | M13: =+I13/J13 -> 0.81984186 | N13: 160-190 | O13: =+O12+1 -> 7 | P13: =+'REGISTRO 1- lote 9'!$H$81 -> 14 | R13: =+R12-P13-Q13 -> 5926 | S13: =+'REGISTRO 1- lote 9'!$H$68 -> 160 | T13: =+S13*1000/R13 -> 26.999663 | U13: =+U12+T13 -> 160.93482 | V13: =+'REGISTRO 1- lote 9'!U68 -> 0 | W13: =+V13-V6 -> -44 | X13: =+(V13-$J$6)/O13 -> -6.2857143 | Y13: =+U13/V13 -> #DIV/0! | Z13: 160-185
A14: =+A13+1 -> 45788 | B14: Semana 2 | C14: =+C13+1 -> 8 | D14: =+'REGISTRO 1- lote 9'!$B$31 -> 4 | F14: =+F13-D14-E14 -> 6450 | G14: =+'REGISTRO 1- lote 9'!$B$18 -> 240 | H14: =+G14*1000/F14 -> 37.209302 | I14: =+I13+H14 -> 197.07847 | O14: =+O13+1 -> 8 | P14: =+'REGISTRO 1- lote 9'!$B$82 -> 5 | R14: =+R13-P14-Q14 -> 5921 | S14: =+'REGISTRO 1- lote 9'!$B$69 -> 200 | T14: =+S14*1000/R14 -> 33.778078 | U14: =+U13+T14 -> 194.7129
A15: =+A14+1 -> 45789 | C15: =+C14+1 -> 9 | D15: =+'REGISTRO 1- lote 9'!$C$31 -> 6 | F15: =+F14-D15-E15 -> 6444 | G15: =+'REGISTRO 1- lote 9'!$C$18 -> 240 | H15: =+G15*1000/F15 -> 37.243948 | I15: =+I14+H15 -> 234.32241 | O15: =+O14+1 -> 9 | P15: =+'REGISTRO 1- lote 9'!$C$82 -> 6 | R15: =+R14-P15-Q15 -> 5915 | S15: =+'REGISTRO 1- lote 9'!$C$69 -> 220 | T15: =+S15*1000/R15 -> 37.193576 | U15: =+U14+T15 -> 231.90647
A16: =+A15+1 -> 45790 | C16: =+C15+1 -> 10 | D16: =+'REGISTRO 1- lote 9'!$D$31 -> 7 | F16: =+F15-D16-E16 -> 6437 | G16: =+'REGISTRO 1- lote 9'!$D$18 -> 280 | H16: =+G16*1000/F16 -> 43.498524 | I16: =+I15+H16 -> 277.82094 | O16: =+O15+1 -> 10 | P16: =+'REGISTRO 1- lote 9'!$D$82 -> 5 | R16: =+R15-P16-Q16 -> 5910 | S16: =+'REGISTRO 1- lote 9'!$D$69 -> 240 | T16: =+S16*1000/R16 -> 40.609137 | U16: =+U15+T16 -> 272.51561
A17: =+A16+1 -> 45791 | C17: =+C16+1 -> 11 | D17: =+'REGISTRO 1- lote 9'!$E$31 -> 7 | F17: =+F16-D17-E17 -> 6430 | G17: =+'REGISTRO 1- lote 9'!$E$18 -> 320 | H17: =+G17*1000/F17 -> 49.766719 | I17: =+I16+H17 -> 327.58766 | O17: =+O16+1 -> 11 | P17: =+'REGISTRO 1- lote 9'!$E$82 -> 7 | R17: =+R16-P17-Q17 -> 5903 | S17: =+'REGISTRO 1- lote 9'!$E$69 -> 280 | T17: =+S17*1000/R17 -> 47.433508 | U17: =+U16+T17 -> 319.94912
A18: =+A17+1 -> 45792 | C18: =+C17+1 -> 12 | D18: =+'REGISTRO 1- lote 9'!$F$31 -> 9 | F18: =+F17-D18-E18 -> 6421 | G18: =+'REGISTRO 1- lote 9'!$F$18 -> 360 | H18: =+G18*1000/F18 -> 56.066033 | I18: =+I17+H18 -> 383.65369 | O18: =+O17+1 -> 12 | P18: =+'REGISTRO 1- lote 9'!$F$82 -> 7 | R18: =+R17-P18-Q18 -> 5896 | S18: =+'REGISTRO 1- lote 9'!$F$69 -> 360 | T18: =+S18*1000/R18 -> 61.058345 | U18: =+U17+T18 -> 381.00746
A19: =+A18+1 -> 45793 | C19: =+C18+1 -> 13 | D19: =+'REGISTRO 1- lote 9'!$G$31 -> 10 | F19: =+F18-D19-E19 -> 6411 | G19: =+'REGISTRO 1- lote 9'!$G$18 -> 380 | H19: =+G19*1000/F19 -> 59.273124 | I19: =+I18+H19 -> 442.92681 | O19: =+O18+1 -> 13 | P19: =+'REGISTRO 1- lote 9'!$G$82 -> 5 | R19: =+R18-P19-Q19 -> 5891 | S19: =+'REGISTRO 1- lote 9'!$G$69 -> 360 | T19: =+S19*1000/R19 -> 61.110168 | U19: =+U18+T19 -> 442.11763
A20: =+A19+1 -> 45794 | C20: =+C19+1 -> 14 | D20: =+'REGISTRO 1- lote 9'!$H$31 -> 14 | F20: =+F19-D20-E20 -> 6397 | G20: =+'REGISTRO 1- lote 9'!$H$18 -> 400 | H20: =+G20*1000/F20 -> 62.529311 | I20: =+I19+H20 -> 505.45612 | J20: =+'REGISTRO 1- lote 9'!U18 -> 455 | K20: =+J20-J13 -> 260 | L20: =+(J20-$J$6)/C20 -> 29.357143 | M20: =+I20/J20 -> 1.1108926 | N20: 380-390 | O20: =+O19+1 -> 14 | P20: =+'REGISTRO 1- lote 9'!$H$82 -> 9 | R20: =+R19-P20-Q20 -> 5882 | S20: =+'REGISTRO 1- lote 9'!$H$69 -> 400 | T20: =+S20*1000/R20 -> 68.00408 | U20: =+U19+T20 -> 510.12171 | V20: =+'REGISTRO 1- lote 9'!U69 -> 195 | W20: =+V20-V13 -> 195 | X20: =+(V20-$J$6)/O20 -> 10.785714 | Y20: =+U20/V20 -> 2.6160088 | Z20: 375-380
A21: =+A20+1 -> 45795 | B21: Semana 3 | C21: =+C20+1 -> 15 | D21: =+'REGISTRO 1- lote 9'!$B$32 -> 5 | F21: =+F20-D21-E21 -> 6392 | G21: =+'REGISTRO 1- lote 9'!$B$19 -> 400 | H21: =+G21*1000/F21 -> 62.578223 | I21: =+I20+H21 -> 568.03435 | O21: =+O20+1 -> 15 | P21: =+'REGISTRO 1- lote 9'!$B$83 -> 2 | R21: =+R20-P21-Q21 -> 5880 | S21: =+'REGISTRO 1- lote 9'!$B$70 -> 440 | T21: =+S21*1000/R21 -> 74.829932 | U21: =+U20+T21 -> 584.95164
A22: =+A21+1 -> 45796 | C22: =+C21+1 -> 16 | D22: =+'REGISTRO 1- lote 9'!$C$32 -> 7 | F22: =+F21-D22-E22 -> 6385 | G22: =+'REGISTRO 1- lote 9'!$C$19 -> 440 | H22: =+G22*1000/F22 -> 68.911511 | I22: =+I21+H22 -> 636.94586 | O22: =+O21+1 -> 16 | P22: =+'REGISTRO 1- lote 9'!$C$83 -> 3 | R22: =+R21-P22-Q22 -> 5877 | S22: =+'REGISTRO 1- lote 9'!$C$70 -> 440 | T22: =+S22*1000/R22 -> 74.86813 | U22: =+U21+T22 -> 659.81977
A23: =+A22+1 -> 45797 | C23: =+C22+1 -> 17 | D23: =+'REGISTRO 1- lote 9'!$D$32 -> 6 | F23: =+F22-D23-E23 -> 6379 | G23: =+'REGISTRO 1- lote 9'!$D$19 -> 480 | H23: =+G23*1000/F23 -> 75.246904 | I23: =+I22+H23 -> 712.19276 | O23: =+O22+1 -> 17 | P23: =+'REGISTRO 1- lote 9'!$D$83 -> 5 | R23: =+R22-P23-Q23 -> 5872 | S23: =+'REGISTRO 1- lote 9'!$D$70 -> 480 | T23: =+S23*1000/R23 -> 81.743869 | U23: =+U22+T23 -> 741.56364
A24: =+A23+1 -> 45798 | C24: =+C23+1 -> 18 | D24: =+'REGISTRO 1- lote 9'!$E$32 -> 8 | F24: =+F23-D24-E24 -> 6371 | G24: =+'REGISTRO 1- lote 9'!$E$19 -> 520 | H24: =+G24*1000/F24 -> 81.61984 | I24: =+I23+H24 -> 793.8126 | O24: =+O23+1 -> 18 | P24: =+'REGISTRO 1- lote 9'!$E$83 -> 2 | R24: =+R23-P24-Q24 -> 5870 | S24: =+'REGISTRO 1- lote 9'!$E$70 -> 480 | T24: =+S24*1000/R24 -> 81.771721 | U24: =+U23+T24 -> 823.33536
A25: =+A24+1 -> 45799 | C25: =+C24+1 -> 19 | D25: =+'REGISTRO 1- lote 9'!$F$32 -> 4 | F25: =+F24-D25-E25 -> 6367 | G25: =+'REGISTRO 1- lote 9'!$F$19 -> 560 | H25: =+G25*1000/F25 -> 87.95351 | I25: =+I24+H25 -> 881.76611 | O25: =+O24+1 -> 19 | P25: =+'REGISTRO 1- lote 9'!$F$83 -> 2 | R25: =+R24-P25-Q25 -> 5868 | S25: =+'REGISTRO 1- lote 9'!$F$70 -> 520 | T25: =+S25*1000/R25 -> 88.616224 | U25: =+U24+T25 -> 911.95159
A26: =+A25+1 -> 45800 | C26: =+C25+1 -> 20 | D26: =+'REGISTRO 1- lote 9'!$G$32 -> 6 | F26: =+F25-D26-E26 -> 6361 | G26: =+'REGISTRO 1- lote 9'!$G$19 -> 600 | H26: =+G26*1000/F26 -> 94.324792 | I26: =+I25+H26 -> 976.0909 | O26: =+O25+1 -> 20 | P26: =+'REGISTRO 1- lote 9'!$G$83 -> 4 | R26: =+R25-P26-Q26 -> 5864 | S26: =+'REGISTRO 1- lote 9'!$G$70 -> 560 | T26: =+S26*1000/R26 -> 95.497954 | U26: =+U25+T26 -> 1007.4495
A27: =+A26+1 -> 45801 | C27: =+C26+1 -> 21 | D27: =+'REGISTRO 1- lote 9'!$H$32 -> 7 | F27: =+F26-D27-E27 -> 6354 | G27: =+'REGISTRO 1- lote 9'!$H$19 -> 600 | H27: =+G27*1000/F27 -> 94.428706 | I27: =+I26+H27 -> 1070.5196 | J27: =+'REGISTRO 1- lote 9'!U19 -> 880 | K27: =+J27-J20 -> 425 | L27: =+(J27-$J$6)/C27 -> 39.809524 | M27: =+I27/J27 -> 1.2164996 | N27: 730-780 | O27: =+O26+1 -> 21 | P27: =+'REGISTRO 1- lote 9'!$H$83 -> 3 | R27: =+R26-P27-Q27 -> 5861 | S27: =+'REGISTRO 1- lote 9'!$H$70 -> 560 | T27: =+S27*1000/R27 -> 95.546835 | U27: =+U26+T27 -> 1102.9964 | V27: =+'REGISTRO 1- lote 9'!U70 -> 455 | W27: =+V27-V20 -> 260 | X27: =+(V27-$J$6)/O27 -> 19.571429 | Y27: =+U27/V27 -> 2.4241679 | Z27: 680-760
A28: =+A27+1 -> 45802 | B28: Semana 4 | C28: =+C27+1 -> 22 | D28: =+'REGISTRO 1- lote 9'!$B$33 -> 3 | F28: =+F27-D28-E28 -> 6351 | G28: =+'REGISTRO 1- lote 9'!$B$20 -> 680 | H28: =+G28*1000/F28 -> 107.06975 | I28: =+I27+H28 -> 1177.5894 | O28: =+O27+1 -> 22 | P28: =+'REGISTRO 1- lote 9'!$B$84 -> 3 | R28: =+R27-P28-Q28 -> 5858 | S28: =+'REGISTRO 1- lote 9'!$B$71 -> 560 | T28: =+S28*1000/R28 -> 95.595766 | U28: =+U27+T28 -> 1198.5921
A29: =+A28+1 -> 45803 | C29: =+C28+1 -> 23 | D29: =+'REGISTRO 1- lote 9'!$C$33 -> 4 | F29: =+F28-D29-E29 -> 6347 | G29: =+'REGISTRO 1- lote 9'!$C$20 -> 720 | H29: =+G29*1000/F29 -> 113.43942 | I29: =+I28+H29 -> 1291.0288 | O29: =+O28+1 -> 23 | P29: =+'REGISTRO 1- lote 9'!$C$84 -> 5 | R29: =+R28-P29-Q29 -> 5853 | S29: =+'REGISTRO 1- lote 9'!$C$71 -> 600 | T29: =+S29*1000/R29 -> 102.51153 | U29: =+U28+T29 -> 1301.1037
A30: =+A29+1 -> 45804 | C30: =+C29+1 -> 24 | D30: =+'REGISTRO 1- lote 9'!$D$33 -> 6 | F30: =+F29-D30-E30 -> 6341 | G30: =+'REGISTRO 1- lote 9'!$D$20 -> 760 | H30: =+G30*1000/F30 -> 119.85491 | I30: =+I29+H30 -> 1410.8837 | O30: =+O29+1 -> 24 | P30: =+'REGISTRO 1- lote 9'!$D$84 -> 2 | R30: =+R29-P30-Q30 -> 5851 | S30: =+'REGISTRO 1- lote 9'!$D$71 -> 640 | T30: =+S30*1000/R30 -> 109.38301 | U30: =+U29+T30 -> 1410.4867
A31: =+A30+1 -> 45805 | C31: =+C30+1 -> 25 | D31: =+'REGISTRO 1- lote 9'!$E$33 -> 3 | F31: =+F30-D31-E31 -> 6338 | G31: =+'REGISTRO 1- lote 9'!$E$20 -> 800 | H31: =+G31*1000/F31 -> 126.22278 | I31: =+I30+H31 -> 1537.1065 | O31: =+O30+1 -> 25 | P31: =+'REGISTRO 1- lote 9'!$E$84 -> 6 | R31: =+R30-P31-Q31 -> 5845 | S31: =+'REGISTRO 1- lote 9'!$E$71 -> 720 | T31: =+S31*1000/R31 -> 123.18221 | U31: =+U30+T31 -> 1533.6689
A32: =+A31+1 -> 45806 | C32: =+C31+1 -> 26 | D32: =+'REGISTRO 1- lote 9'!$F$33 -> 5 | F32: =+F31-D32-E32 -> 6333 | G32: =+'REGISTRO 1- lote 9'!$F$20 -> 840 | H32: =+G32*1000/F32 -> 132.63856 | I32: =+I31+H32 -> 1669.745 | O32: =+O31+1 -> 26 | P32: =+'REGISTRO 1- lote 9'!$F$84 -> 4 | R32: =+R31-P32-Q32 -> 5841 | S32: =+'REGISTRO 1- lote 9'!$F$71 -> 760 | T32: =+S32*1000/R32 -> 130.11471 | U32: =+U31+T32 -> 1663.7836
A33: =+A32+1 -> 45807 | C33: =+C32+1 -> 27 | D33: =+'REGISTRO 1- lote 9'!$G$33 -> 4 | F33: =+F32-D33-E33 -> 6329 | G33: =+'REGISTRO 1- lote 9'!$G$20 -> 880 | H33: =+G33*1000/F33 -> 139.0425 | I33: =+I32+H33 -> 1808.7875 | O33: =+O32+1 -> 27 | P33: =+'REGISTRO 1- lote 9'!$G$84 -> 5 | R33: =+R32-P33-Q33 -> 5836 | S33: =+'REGISTRO 1- lote 9'!$G$71 -> 760 | T33: =+S33*1000/R33 -> 130.22618 | U33: =+U32+T33 -> 1794.0098
A34: =+A33+1 -> 45808 | C34: =+C33+1 -> 28 | D34: =+'REGISTRO 1- lote 9'!$H$33 -> 3 | F34: =+F33-D34-E34 -> 6326 | G34: =+'REGISTRO 1- lote 9'!$H$20 -> 880 | H34: =+G34*1000/F34 -> 139.10844 | I34: =+I33+H34 -> 1947.896 | J34: =+'REGISTRO 1- lote 9'!U20 -> 1450 | K34: =+J34-J27 -> 570 | L34: =+(J34-$J$6)/C34 -> 50.214286 | M34: =+I34/J34 -> 1.3433765 | N34: 1210-1350 | O34: =+O33+1 -> 28 | P34: =+'REGISTRO 1- lote 9'!$H$84 -> 6 | R34: =+R33-P34-Q34 -> 5830 | S34: =+'REGISTRO 1- lote 9'!$H$71 -> 800 | T34: =+S34*1000/R34 -> 137.22127 | U34: =+U33+T34 -> 1931.231 | V34: =+'REGISTRO 1- lote 9'!U71 -> 865 | W34: =+V34-V27 -> 410 | X34: =+(V34-$J$6)/O34 -> 29.321429 | Y34: =+U34/V34 -> 2.2326371 | Z34: 1150-1320
A35: =+A34+1 -> 45809 | B35: Semana 5 | C35: =+C34+1 -> 29 | D35: =+'REGISTRO 1- lote 9'!$B$34 -> 9 | F35: =+F34-D35-E35 -> 6317 | G35: =+'REGISTRO 1- lote 9'!$B$21 -> 920 | H35: =+G35*1000/F35 -> 145.63875 | I35: =+I34+H35 -> 2093.5347 | O35: =+O34+1 -> 29 | P35: =+'REGISTRO 1- lote 9'!$B$85 -> 3 | R35: =+R34-P35-Q35 -> 5827 | S35: =+'REGISTRO 1- lote 9'!$B$72 -> 800 | T35: =+S35*1000/R35 -> 137.29192 | U35: =+U34+T35 -> 2068.523
A36: =+A35+1 -> 45810 | C36: =+C35+1 -> 30 | D36: =+'REGISTRO 1- lote 9'!$C$34 -> 7 | F36: =+F35-D36-E36 -> 6310 | G36: =+'REGISTRO 1- lote 9'!$C$21 -> 920 | H36: =+G36*1000/F36 -> 145.80032 | I36: =+I35+H36 -> 2239.3351 | O36: =+O35+1 -> 30 | P36: =+'REGISTRO 1- lote 9'!$C$85 -> 4 | R36: =+R35-P36-Q36 -> 5823 | S36: =+'REGISTRO 1- lote 9'!$C$72 -> 800 | T36: =+S36*1000/R36 -> 137.38623 | U36: =+U35+T36 -> 2205.9092
A37: =+A36+1 -> 45811 | C37: =+C36+1 -> 31 | D37: =+'REGISTRO 1- lote 9'!$D$34 -> 8 | F37: =+F36-D37-E37 -> 6302 | G37: =+'REGISTRO 1- lote 9'!$D$21 -> 960 | H37: =+G37*1000/F37 -> 152.33259 | I37: =+I36+H37 -> 2391.6676 | O37: =+O36+1 -> 31 | P37: =+'REGISTRO 1- lote 9'!$D$85 -> 2 | R37: =+R36-P37-Q37 -> 5821 | S37: =+'REGISTRO 1- lote 9'!$D$72 -> 840 | T37: =+S37*1000/R37 -> 144.3051 | U37: =+U36+T37 -> 2350.2143
A38: =+A37+1 -> 45812 | C38: =+C37+1 -> 32 | D38: =+'REGISTRO 1- lote 9'!$E$34 -> 10 | F38: =+F37-D38-E38 -> 6292 | G38: =+'REGISTRO 1- lote 9'!$E$21 -> 1000 | H38: =+G38*1000/F38 -> 158.93198 | I38: =+I37+H38 -> 2550.5996 | O38: =+O37+1 -> 32 | P38: =+'REGISTRO 1- lote 9'!$E$85 -> 3 | R38: =+R37-P38-Q38 -> 5818 | S38: =+'REGISTRO 1- lote 9'!$E$72 -> 840 | T38: =+S38*1000/R38 -> 144.37951 | U38: =+U37+T38 -> 2494.5938
A39: =+A38+1 -> 45813 | C39: =+C38+1 -> 33 | D39: =+'REGISTRO 1- lote 9'!$F$34 -> 9 | F39: =+F38-D39-E39 -> 6283 | G39: =+'REGISTRO 1- lote 9'!$F$21 -> 1000 | H39: =+G39*1000/F39 -> 159.15964 | I39: =+I38+H39 -> 2709.7593 | O39: =+O38+1 -> 33 | P39: =+'REGISTRO 1- lote 9'!$F$85 -> 4 | R39: =+R38-P39-Q39 -> 5814 | S39: =+'REGISTRO 1- lote 9'!$F$72 -> 880 | T39: =+S39*1000/R39 -> 151.35879 | U39: =+U38+T39 -> 2645.9526
A40: =+A39+1 -> 45814 | C40: =+C39+1 -> 34 | D40: =+'REGISTRO 1- lote 9'!$G$34 -> 10 | F40: =+F39-D40-E40 -> 6273 | G40: =+'REGISTRO 1- lote 9'!$G$21 -> 1040 | H40: =+G40*1000/F40 -> 165.78989 | I40: =+I39+H40 -> 2875.5492 | O40: =+O39+1 -> 34 | P40: =+'REGISTRO 1- lote 9'!$G$85 -> 6 | R40: =+R39-P40-Q40 -> 5808 | S40: =+'REGISTRO 1- lote 9'!$G$72 -> 880 | T40: =+S40*1000/R40 -> 151.51515 | U40: =+U39+T40 -> 2797.4677
...

Sheet REGISTRO 2- lote 10
B1: AVICOLA SAN LORENZO
B2: GRANJA : | E2: =+'REGISTRO 1- lote 9'!E2 -> SAN LORENZO
B3: RESPONSABLE : | E3: =+'REGISTRO 1- lote 9'!E3 -> 0 | O3: MACHO
B5: GALPON | D5: LOTE | G5: INCUBADORA | K5: CANTIDAD INICIAL | O5: PESO PROMEDIO INIC.
B6: =+'REGISTRO 1- lote 9'!B6:C6 -> T1 | D6: =+'REGISTRO 1- lote 9'!D6:E6 -> 49 | G6: =+'REGISTRO 1- lote 9'!G6:J6 -> FINAVES | K6: 4660 | O6: 44
B8: FECHA INICIO | G8: =+'REGISTRO 1- lote 9'!G8:J8 -> 45780 | L8: DIAS DE ENGORDE: | P8: =(G9-G8)+1 -> 52
B9: FECHA TERMINACION | G9: =+PESAS!B19 -> 45831 | L9: DIAS PROMEDIO | P9: =+#REF! -> #REF!
B11: POLLOS VENDIDOS | Z11: conversion: kilos concentrado/ kilos en pie
B12: PESO TOTAL FINAL | L12: CONSUMO TOTAL DEL LOTE | Z12: se necesita xxx kilos concentrado para producir 1 kilo de pollo en pie
Z13: Entre mas bajo mejor
I14: TOTAL CONSUMO | Q14: CONSUMO POR AVE | U14: PESO
A15: KILOS CONSUMIDOS | I15: SEMANAL | M15: ACUMULADO | Q15: (Gramos) | T15: CONSUMO | U15: GRAMOS | V15: gramos | Z15: BULTOS CONSUMIDOS
A16: S/D | B16: =+'REGISTRO 1- lote 9'!B16 -> S | C16: =+'REGISTRO 1- lote 9'!C16 -> D | D16: =+'REGISTRO 1- lote 9'!D16 -> L | E16: =+'REGISTRO 1- lote 9'!E16 -> M | F16: =+'REGISTRO 1- lote 9'!F16 -> M | G16: =+'REGISTRO 1- lote 9'!G16 -> J | H16: =+'REGISTRO 1- lote 9'!H16 -> V | I16: Bultos | K16: Kilos | M16: Bultos | O16: Kilos | Q16: Diario | R16: Sem. | S16: Acumul. | T16: KL. | U16: PROMEDIO | V16: Ganancia dia | W16: Conversion | X16: VPI | Z16: S/D | AA16: =+B16 -> S | AB16: =+C16 -> D | AC16: =+D16 -> L | AD16: =+E16 -> M | AE16: =+F16 -> M | AF16: =+G16 -> J | AG16: =+H16 -> V | AH16: TOTAL
A17: 1 | B17: =+AA17*40 -> 80 | C17: =+AB17*40 -> 80 | D17: =+AC17*40 -> 80 | E17: =+AD17*40 -> 100 | F17: =+AE17*40 -> 120 | G17: =+AF17*40 -> 120 | H17: =+AG17*40 -> 160 | I17: =+K17/40 -> 18.5 | K17: =SUM(B17:H17) -> 740 | M17: =+I17 -> 18.5 | O17: =+K17 -> 740 | Q17: =+R17/7 -> 23.132229 | R17: =+K17*1000/S30 -> 161.9256 | S17: =+R17 -> 161.9256 | T17: =+O17/S30 -> 0.1619256 | U17: 193 | V17: =(U17-O6)/7 -> 21.285714 | W17: =+O17/(S30*(U17/1000)) -> 0.83899276 | X17: =+U17/O6 -> 4.3863636 | Z17: 1 | AA17: 2 | AB17: 2 | AC17: 2 | AD17: 2.5 | AE17: 3 | AF17: 3 | AG17: 4 | AH17: =+SUM(AA17:AG17) -> 18.5
A18: 2 | B18: =+AA18*40 -> 160 | C18: =+AB18*40 -> 160 | D18: =+AC18*40 -> 200 | E18: =+AD18*40 -> 240 | F18: =+AE18*40 -> 240 | G18: =+AF18*40 -> 280 | H18: =+AG18*40 -> 320 | I18: =+K18/40 -> 40 | K18: =SUM(B18:H18) -> 1600 | M18: =+M17+I18 -> 58.5 | O18: =+O17+K18 -> 2340 | Q18: =+R18/7 -> 50.368318 | R18: =+K18*1000/S31 -> 352.57823 | S18: =+O18*1000/S31 -> 515.64566 | T18: =+O18/S31 -> 0.51564566 | U18: 455 | V18: =+(U18-U17)/7 -> 37.428571 | W18: =+O18/(S31*(U18/1000)) -> 1.1332872 | X18: =+U18/U17 -> 2.357513 | Z18: 2 | AA18: 4 | AB18: 4 | AC18: 5 | AD18: 6 | AE18: 6 | AF18: 7 | AG18: 8 | AH18: =+SUM(AA18:AG18) -> 40
A19: 3 | B19: =+AA19*40 -> 320 | C19: =+AB19*40 -> 320 | D19: =+AC19*40 -> 360 | E19: =+AD19*40 -> 360 | F19: =+AE19*40 -> 400 | G19: =+AF19*40 -> 440 | H19: =+AG19*40 -> 480 | I19: =+K19/40 -> 67 | K19: =SUM(B19:H19) -> 2680 | M19: =+M18+I19 -> 125.5 | O19: =+O18+K19 -> 5020 | Q19: =+R19/7 -> 84.721651 | R19: =+K19*1000/S32 -> 593.05156 | S19: =+O19*1000/S32 -> 1110.8652 | T19: =+O19/S32 -> 1.1108652 | U19: 880 | V19: =+(U19-U18)/7 -> 60.714286 | W19: =+O19/(S32*(U19/1000)) -> 1.2623469 | X19: =+U19/U18 -> 1.9340659 | Z19: 3 | AA19: 8 | AB19: 8 | AC19: 9 | AD19: 9 | AE19: 10 | AF19: 11 | AG19: 12 | AH19: =+SUM(AA19:AG19) -> 67
A20: 4 | B20: =+AA20*40 -> 480 | C20: =+AB20*40 -> 480 | D20: =+AC20*40 -> 520 | E20: =+AD20*40 -> 560 | F20: =+AE20*40 -> 600 | G20: =+AF20*40 -> 640 | H20: =+AG20*40 -> 640 | I20: =+K20/40 -> 98 | K20: =SUM(B20:H20) -> 3920 | M20: =+M19+I20 -> 223.5 | O20: =+O19+K20 -> 8940 | Q20: =+R20/7 -> 124.49978 | R20: =+K20*1000/S33 -> 871.49844 | S20: =+O20*1000/S33 -> 1987.55 | T20: =+O20/S33 -> 1.98755 | U20: 1450 | V20: =+(U20-U19)/7 -> 81.428571 | W20: =+O20/(S33*(U20/1000)) -> 1.3707242 | X20: =+U20/U19 -> 1.6477273 | Z20: 4 | AA20: 12 | AB20: 12 | AC20: 13 | AD20: 14 | AE20: 15 | AF20: 16 | AG20: 16 | AH20: =+SUM(AA20:AG20) -> 98
A21: 5 | B21: =+AA21*40 -> 640 | C21: =+AB21*40 -> 640 | D21: =+AC21*40 -> 680 | E21: =+AD21*40 -> 680 | F21: =+AE21*40 -> 720 | G21: =+AF21*40 -> 720 | H21: =+AG21*40 -> 720 | I21: =+K21/40 -> 120 | K21: =SUM(B21:H21) -> 4800 | M21: =+M20+I21 -> 343.5 | O21: =+O20+K21 -> 13740 | Q21: =+R21/7 -> 153.57543 | R21: =+K21*1000/S34 -> 1075.028 | S21: =+O21*1000/S34 -> 3077.2676 | T21: =+O21/S34 -> 3.0772676 | U21: 8040 | V21: =+(U21-U20)/7 -> 941.42857 | W21: =+O21/(S34*(U21/1000)) -> 0.38274473 | X21: =+U21/U20 -> 5.5448276 | Z21: 5 | AA21: 16 | AB21: 16 | AC21: 17 | AD21: 17 | AE21: 18 | AF21: 18 | AG21: 18 | AH21: =+SUM(AA21:AG21) -> 120
A22: 6 | B22: =+AA22*40 -> 720 | C22: =+AB22*40 -> 720 | D22: =+AC22*40 -> 760 | E22: =+AD22*40 -> 760 | F22: =+AE22*40 -> 760 | G22: =+AF22*40 -> 760 | H22: =+AG22*40 -> 760 | I22: =+K22/40 -> 131 | K22: =SUM(B22:H22) -> 5240 | M22: =+M21+I22 -> 474.5 | O22: =+O21+K22 -> 18980 | Q22: =+R22/7 -> 168.9015 | R22: =+K22*1000/S35 -> 1182.3105 | S22: =+O22*1000/S35 -> 4282.491 | T22: =+O22/S35 -> 4.282491 | U22: 2660 | V22: =+(U22-U21)/7 -> -768.57143 | W22: =+O22/(S35*(U22/1000)) -> 1.609959 | X22: =+U22/U21 -> 0.33084577 | Z22: 6 | AA22: 18 | AB22: 18 | AC22: 19 | AD22: 19 | AE22: 19 | AF22: 19 | AG22: 19 | AH22: =+SUM(AA22:AG22) -> 131
A23: 7 | B23: =+AA23*40 -> 720 | C23: =+AB23*40 -> 720 | D23: =+AC23*40 -> 720 | E23: =+AD23*40 -> 720 | F23: =+AE23*40 -> 600 | G23: =+AF23*40 -> 400 | H23: =+AG23*40 -> 0 | I23: =+K23/40 -> 97 | K23: =SUM(B23:H23) -> 3880 | M23: =+M22+I23 -> 571.5 | O23: =+O22+K23 -> 22860 | Q23: =+R23/7 -> 126.03131 | R23: =+K23*1000/S36 -> 882.21919 | S23: =+O23*1000/S36 -> 5197.8172 | T23: =+O23/S36 -> 5.1978172 | V23: =+(U23-U22)/7 -> -380 | W23: =+O23/(S36*(U23/1000)) -> #DIV/0! | X23: =+U23/U22 -> 0 | Z23: 7 | AA23: 18 | AB23: 18 | AC23: 18 | AD23: 18 | AE23: 15 | AF23: 10 | AH23: =+SUM(AA23:AG23) -> 97
A24: 8 | B24: =+AA24*40 -> 0 | C24: =+AB24*40 -> 0 | D24: =+AC24*40 -> 0 | E24: =+AD24*40 -> 0 | F24: =+AE24*40 -> 0 | G24: =+AF24*40 -> 0 | H24: =+AG24*40 -> 0 | I24: =+K24/40 -> 0 | K24: =SUM(B24:H24) -> 0 | M24: =+M23+I24 -> 571.5 | O24: =+O23+K24 -> 22860 | Q24: =+R24/7 -> 0 | R24: =+K24*1000/S37 -> 0 | S24: =+O24*1000/S37 -> 5197.8172 | T24: =+O24/S37 -> 5.1978172 | V24: =+(U24-U23)/7 -> 0 | W24: =+O24/(S37*(U24/1000)) -> #DIV/0! | X24: =+U24/U23 -> #DIV/0! | Z24: 8 | AH24: =+SUM(AA24:AG24) -> 0
A25: 9 | B25: =+AA25*40 -> 0 | C25: =+AB25*40 -> 0 | D25: =+AC25*40 -> 0 | E25: =+AD25*40 -> 0 | F25: =+AE25*40 -> 0 | G25: =+AF25*40 -> 0 | H25: =+AG25*40 -> 0 | I25: =+K25/40 -> 0 | K25: =SUM(B25:H25) -> 0 | M25: =+M24+I25 -> 571.5 | O25: =+O24+K25 -> 22860 | Q25: =+R25/7 -> 0 | R25: =+K25*1000/S38 -> 0 | S25: =+O25*1000/S38 -> 5197.8172 | T25: =+O25/S38 -> 5.1978172 | V25: =+(U25-U24)/7 -> 0 | W25: =+O25/(S38*(U25/1000)) -> #DIV/0! | X25: =+U25/U24 -> #DIV/0! | Z25: 9 | AH25: =+SUM(AA25:AG25) -> 0
I27: TOTAL MORTALIDAD Y SELECCIÓN | S27: SALDO
B28: AVES MUERTAS POR DIA | I28: Mort./sem. | K28: Selec/Sem | M28: Mort.Acum. | O28: Selec.Acum. | Q28: Mort/Selec.Ac. | S28: AVES
A29: S/D | B29: =+B16 -> S | C29: =+C16 -> D | D29: =+D16 -> L | E29: =+E16 -> M | F29: =+F16 -> M | G29: =+G16 -> J | H29: =+H16 -> V | I29: No.A. | J29: % | K29: No.A. | L29: % | M29: No.A. | N29: % | O29: No.A. | P29: % | Q29: No.A. | R29: % | S29: (superv.)
A30: 1 | B30: =2+4 -> 6 | C30: =2+4 -> 6 | D30: =3+7 -> 10 | E30: =7+11 -> 18 | F30: 16 | G30: =9+7 -> 16 | H30: 18 | I30: =SUM(B30:H30) -> 90 | J30: =+I30/K6 -> 0.019313305 | M30: =+I30 -> 90 | N30: =+M30/K$6 -> 0.019313305 | Q30: =+M30+O30 -> 90 | R30: =+Q30/$K$6 -> 0.019313305 | S30: =+K6-I30-K30 -> 4570
A31: 2 | B31: 3 | C31: 4 | D31: 6 | E31: 5 | F31: 3 | G31: 4 | H31: 7 | I31: =SUM(B31:H31) -> 32 | J31: =+I31/S30 -> 0.0070021882 | M31: =+M30+I31 -> 122 | N31: =+M31/K$6 -> 0.026180258 | Q31: =+M31+O31 -> 122 | R31: =+Q31/$K$6 -> 0.026180258 | S31: =+S30-I31-K31 -> 4538
A32: 3 | B32: 3 | C32: 2 | D32: 3 | E32: 1 | F32: 4 | G32: 3 | H32: 3 | I32: =SUM(B32:H32) -> 19 | J32: =+I32/S31 -> 0.0041868665 | M32: =+M31+I32 -> 141 | N32: =+M32/K$6 -> 0.030257511 | Q32: =+M32+O32 -> 141 | R32: =+Q32/$K$6 -> 0.030257511 | S32: =+S31-I32-K32 -> 4519
A33: 4 | B33: 2 | C33: 1 | D33: 3 | E33: 2 | F33: 4 | G33: 3 | H33: 6 | I33: =SUM(B33:H33) -> 21 | J33: =+I33/S32 -> 0.0046470458 | M33: =+M32+I33 -> 162 | N33: =+M33/K$6 -> 0.034763948 | Q33: =+M33+O33 -> 162 | R33: =+Q33/$K$6 -> 0.034763948 | S33: =+S32-I33-K33 -> 4498
A34: 5 | B34: 4 | C34: 4 | D34: 6 | E34: 3 | F34: 4 | G34: 7 | H34: 5 | I34: =SUM(B34:H34) -> 33 | J34: =+I34/S33 -> 0.007336594 | M34: =+M33+I34 -> 195 | N34: =+M34/K$6 -> 0.041845494 | Q34: =+M34+O34 -> 195 | R34: =+Q34/$K$6 -> 0.041845494 | S34: =+S33-I34-K34 -> 4465
A35: 6 | B35: 3 | C35: 4 | D35: 5 | E35: 6 | F35: 5 | G35: 4 | H35: 6 | I35: =SUM(B35:H35) -> 33 | J35: =+I35/S34 -> 0.0073908175 | M35: =+M34+I35 -> 228 | N35: =+M35/K$6 -> 0.048927039 | Q35: =+M35+O35 -> 228 | R35: =+Q35/$K$6 -> 0.048927039 | S35: =+S34-I35-K35 -> 4432
A36: 7 | B36: 4 | C36: 5 | D36: 6 | E36: 5 | F36: 4 | G36: 4 | H36: 6 | I36: =SUM(B36:H36) -> 34 | J36: =+I36/S35 -> 0.0076714801 | M36: =+M35+I36 -> 262 | N36: =+M36/K$6 -> 0.056223176 | Q36: =+M36+O36 -> 262 | R36: =+Q36/$K$6 -> 0.056223176 | S36: =+S35-I36-K36 -> 4398
A37: 8 | I37: =SUM(B37:H37) -> 0 | J37: =+I37/S36 -> 0 | M37: =+M36+I37 -> 262 | N37: =+M37/K$6 -> 0.056223176 | Q37: =+M37+O37 -> 262 | R37: =+Q37/$K$6 -> 0.056223176 | S37: =+S36-I37-K37 -> 4398
A38: 9 | I38: =SUM(B38:H38) -> 0 | J38: =+I38/S37 -> 0 | M38: =+M37+I38 -> 262 | N38: =+M38/K$6 -> 0.056223176 | Q38: =+M38+O38 -> 262 | R38: =+Q38/$K$6 -> 0.056223176 | S38: =+S37-I38-K38 -> 4398
B40: PESO POR AVE | E40: Aumento | G40: Conversion | I40: PROGRAMA DE VACUNACION | O40: TRATAMIENTO
A41: S/D | B41: Mach | C41: Hemb. | D41: Prom. | E41: por ave/dia | G41: alimento | I41: DIA | J41: MES | K41: VACUNA | O41: DIA | P41: MES | Q41: DROGA / DOSIS
A42: 1 | D42: =+(B42+C42)/2 -> 0 | E42: =+D42/7 -> 0 | G42: =+S17/D42 -> #DIV/0!
A43: 2 | D43: =+(B43+C43)/2 -> 0 | E43: =(D43-D42)/7 -> 0 | G43: =+S18/D43 -> #DIV/0!
A44: 3 | D44: =+(B44+C44)/2 -> 0 | E44: =(D44-D43)/7 -> 0 | G44: =+S19/D44 -> #DIV/0!
A45: 4 | D45: =+(B45+C45)/2 -> 0 | E45: =(D45-D44)/7 -> 0 | G45: =+S20/D45 -> #DIV/0!
...

Sheet CONSUMO DIARIO 2
A1: GRANJA | B1: =+'REGISTRO 2- lote 10'!E2 -> SAN LORENZO
A2: GALPON: | B2: =+'REGISTRO 2- lote 10'!B6 -> T1 | C2: MACHOS | O2: HEMBRAS
A3: LOTE | B3: =+'REGISTRO 2- lote 10'!D6 -> 49
G4: CONSUMO DIARIO | S4: CONSUMO DIARIO
A5: FECHA | B5: SEMANA | C5: DIA | D5: MORTALIDAD | E5: SALIDA A PROCESO | F5: SALDO POLLITOS | G5: TOTAL KL | H5: X POLLO GR | I5: Acumul X P (gr) | J5: Peso pollito gr | K5: ganancia peso gr semanal | L5: Promedio ganancia peso gr dia | M5: CONVERSION | O5: DIA | P5: MORTALIDAD | Q5: SALIDA A PROCESO | R5: SALDO POLLITOS | S5: TOTAL KL | T5: X POLLO GR | U5: Acumul X P (gr) | V5: Peso pollito gr | W5: ganancia peso gr semanal | X5: Promedio ganancia peso gr dia | Y5: CONVERSION
A6: =+'REGISTRO 2- lote 10'!G8 -> 45780 | B6: Semana 1 | C6: 0 | F6: =+'REGISTRO 2- lote 10'!K6 -> 4660 | J6: =+'REGISTRO 2- lote 10'!O6 -> 44 | O6: 0 | R6: =+'REGISTRO 2- lote 10'!K57 -> 5100 | V6: =+'REGISTRO 2- lote 10'!O57 -> 44
A7: =+A6+1 -> 45781 | C7: 1 | D7: =+'REGISTRO 2- lote 10'!$B$30 -> 6 | F7: =+F6-D7-E7 -> 4654 | G7: =+'REGISTRO 2- lote 10'!$B$17 -> 80 | H7: =+G7*1000/F7 -> 17.189514 | I7: =+H7 -> 17.189514 | O7: 1 | P7: =+'REGISTRO 2- lote 10'!$B$81 -> 9 | R7: =+R6-P7-Q7 -> 5091 | S7: =+'REGISTRO 2- lote 10'!$B$68 -> 80 | T7: =+S7*1000/R7 -> 15.714005 | U7: =+T7 -> 15.714005
A8: =+A7+1 -> 45782 | C8: =+C7+1 -> 2 | D8: =+'REGISTRO 2- lote 10'!$C$30 -> 6 | F8: =+F7-D8-E8 -> 4648 | G8: =+'REGISTRO 2- lote 10'!$C$17 -> 80 | H8: =+G8*1000/F8 -> 17.211704 | I8: =+I7+H8 -> 34.401218 | O8: =+O7+1 -> 2 | P8: =+'REGISTRO 2- lote 10'!$C$81 -> 6 | R8: =+R7-P8-Q8 -> 5085 | S8: =+'REGISTRO 2- lote 10'!$C$68 -> 80 | T8: =+S8*1000/R8 -> 15.732547 | U8: =+U7+T8 -> 31.446552
A9: =+A8+1 -> 45783 | C9: =+C8+1 -> 3 | D9: =+'REGISTRO 2- lote 10'!$D$30 -> 10 | F9: =+F8-D9-E9 -> 4638 | G9: =+'REGISTRO 2- lote 10'!$D$17 -> 80 | H9: =+G9*1000/F9 -> 17.248814 | I9: =+I8+H9 -> 51.650032 | O9: =+O8+1 -> 3 | P9: =+'REGISTRO 2- lote 10'!$D$81 -> 6 | R9: =+R8-P9-Q9 -> 5079 | S9: =+'REGISTRO 2- lote 10'!$D$68 -> 100 | T9: =+S9*1000/R9 -> 19.688915 | U9: =+U8+T9 -> 51.135467
A10: =+A9+1 -> 45784 | C10: =+C9+1 -> 4 | D10: =+'REGISTRO 2- lote 10'!$E$30 -> 18 | F10: =+F9-D10-E10 -> 4620 | G10: =+'REGISTRO 2- lote 10'!$E$17 -> 100 | H10: =+G10*1000/F10 -> 21.645022 | I10: =+I9+H10 -> 73.295054 | O10: =+O9+1 -> 4 | P10: =+'REGISTRO 2- lote 10'!$E$81 -> 12 | R10: =+R9-P10-Q10 -> 5067 | S10: =+'REGISTRO 2- lote 10'!$E$68 -> 120 | T10: =+S10*1000/R10 -> 23.682652 | U10: =+U9+T10 -> 74.818119
A11: =+A10+1 -> 45785 | C11: =+C10+1 -> 5 | D11: =+'REGISTRO 2- lote 10'!$F$30 -> 16 | F11: =+F10-D11-E11 -> 4604 | G11: =+'REGISTRO 2- lote 10'!$F$17 -> 120 | H11: =+G11*1000/F11 -> 26.064292 | I11: =+I10+H11 -> 99.359346 | O11: =+O10+1 -> 5 | P11: =+'REGISTRO 2- lote 10'!$F$81 -> 11 | R11: =+R10-P11-Q11 -> 5056 | S11: =+'REGISTRO 2- lote 10'!$F$68 -> 120 | T11: =+S11*1000/R11 -> 23.734177 | U11: =+U10+T11 -> 98.552297
A12: =+A11+1 -> 45786 | C12: =+C11+1 -> 6 | D12: =+'REGISTRO 2- lote 10'!$G$30 -> 16 | F12: =+F11-D12-E12 -> 4588 | G12: =+'REGISTRO 2- lote 10'!$G$17 -> 120 | H12: =+G12*1000/F12 -> 26.155187 | I12: =+I11+H12 -> 125.51453 | O12: =+O11+1 -> 6 | P12: =+'REGISTRO 2- lote 10'!$G$81 -> 5 | R12: =+R11-P12-Q12 -> 5051 | S12: =+'REGISTRO 2- lote 10'!$G$68 -> 120 | T12: =+S12*1000/R12 -> 23.757672 | U12: =+U11+T12 -> 122.30997
A13: =+A12+1 -> 45787 | C13: =+C12+1 -> 7 | D13: =+'REGISTRO 2- lote 10'!$H$30 -> 18 | F13: =+F12-D13-E13 -> 4570 | G13: =+'REGISTRO 2- lote 10'!$H$17 -> 160 | H13: =+G13*1000/F13 -> 35.010941 | I13: =+I12+H13 -> 160.52547 | J13: =+'REGISTRO 2- lote 10'!U17 -> 193 | K13: =+J13-J6 -> 149 | L13: =+(J13-$J$6)/C13 -> 21.285714 | M13: =+I13/J13 -> 0.83173821 | N13: 160-190 | O13: =+O12+1 -> 7 | P13: =+'REGISTRO 2- lote 10'!$H$81 -> 11 | R13: =+R12-P13-Q13 -> 5040 | S13: =+'REGISTRO 2- lote 10'!$H$68 -> 160 | T13: =+S13*1000/R13 -> 31.746032 | U13: =+U12+T13 -> 154.056 | V13: =+'REGISTRO 2- lote 10'!U68 -> 190 | W13: =+V13-V6 -> 146 | X13: =+(V13-$J$6)/O13 -> 20.857143 | Y13: =+U13/V13 -> 0.81082105 | Z13: 160-185
A14: =+A13+1 -> 45788 | B14: Semana 2 | C14: =+C13+1 -> 8 | D14: =+'REGISTRO 2- lote 10'!$B$31 -> 3 | F14: =+F13-D14-E14 -> 4567 | G14: =+'REGISTRO 2- lote 10'!$B$18 -> 160 | H14: =+G14*1000/F14 -> 35.033939 | I14: =+I13+H14 -> 195.55941 | O14: =+O13+1 -> 8 | P14: =+'REGISTRO 2- lote 10'!$B$82 -> 4 | R14: =+R13-P14-Q14 -> 5036 | S14: =+'REGISTRO 2- lote 10'!$B$69 -> 160 | T14: =+S14*1000/R14 -> 31.771247 | U14: =+U13+T14 -> 185.82725
A15: =+A14+1 -> 45789 | C15: =+C14+1 -> 9 | D15: =+'REGISTRO 2- lote 10'!$C$31 -> 4 | F15: =+F14-D15-E15 -> 4563 | G15: =+'REGISTRO 2- lote 10'!$C$18 -> 160 | H15: =+G15*1000/F15 -> 35.06465 | I15: =+I14+H15 -> 230.62406 | O15: =+O14+1 -> 9 | P15: =+'REGISTRO 2- lote 10'!$C$82 -> 7 | R15: =+R14-P15-Q15 -> 5029 | S15: =+'REGISTRO 2- lote 10'!$C$69 -> 200 | T15: =+S15*1000/R15 -> 39.769338 | U15: =+U14+T15 -> 225.59658
A16: =+A15+1 -> 45790 | C16: =+C15+1 -> 10 | D16: =+'REGISTRO 2- lote 10'!$D$31 -> 6 | F16: =+F15-D16-E16 -> 4557 | G16: =+'REGISTRO 2- lote 10'!$D$18 -> 200 | H16: =+G16*1000/F16 -> 43.888523 | I16: =+I15+H16 -> 274.51259 | O16: =+O15+1 -> 10 | P16: =+'REGISTRO 2- lote 10'!$D$82 -> 6 | R16: =+R15-P16-Q16 -> 5023 | S16: =+'REGISTRO 2- lote 10'!$D$69 -> 200 | T16: =+S16*1000/R16 -> 39.816843 | U16: =+U15+T16 -> 265.41343
A17: =+A16+1 -> 45791 | C17: =+C16+1 -> 11 | D17: =+'REGISTRO 2- lote 10'!$E$31 -> 5 | F17: =+F16-D17-E17 -> 4552 | G17: =+'REGISTRO 2- lote 10'!$E$18 -> 240 | H17: =+G17*1000/F17 -> 52.724077 | I17: =+I16+H17 -> 327.23666 | O17: =+O16+1 -> 11 | P17: =+'REGISTRO 2- lote 10'!$E$82 -> 6 | R17: =+R16-P17-Q17 -> 5017 | S17: =+'REGISTRO 2- lote 10'!$E$69 -> 240 | T17: =+S17*1000/R17 -> 47.837353 | U17: =+U16+T17 -> 313.25078
A18: =+A17+1 -> 45792 | C18: =+C17+1 -> 12 | D18: =+'REGISTRO 2- lote 10'!$F$31 -> 3 | F18: =+F17-D18-E18 -> 4549 | G18: =+'REGISTRO 2- lote 10'!$F$18 -> 240 | H18: =+G18*1000/F18 -> 52.758848 | I18: =+I17+H18 -> 379.99551 | O18: =+O17+1 -> 12 | P18: =+'REGISTRO 2- lote 10'!$F$82 -> 5 | R18: =+R17-P18-Q18 -> 5012 | S18: =+'REGISTRO 2- lote 10'!$F$69 -> 280 | T18: =+S18*1000/R18 -> 55.865922 | U18: =+U17+T18 -> 369.1167
A19: =+A18+1 -> 45793 | C19: =+C18+1 -> 13 | D19: =+'REGISTRO 2- lote 10'!$G$31 -> 4 | F19: =+F18-D19-E19 -> 4545 | G19: =+'REGISTRO 2- lote 10'!$G$18 -> 280 | H19: =+G19*1000/F19 -> 61.606161 | I19: =+I18+H19 -> 441.60167 | O19: =+O18+1 -> 13 | P19: =+'REGISTRO 2- lote 10'!$G$82 -> 7 | R19: =+R18-P19-Q19 -> 5005 | S19: =+'REGISTRO 2- lote 10'!$G$69 -> 280 | T19: =+S19*1000/R19 -> 55.944056 | U19: =+U18+T19 -> 425.06076
A20: =+A19+1 -> 45794 | C20: =+C19+1 -> 14 | D20: =+'REGISTRO 2- lote 10'!$H$31 -> 7 | F20: =+F19-D20-E20 -> 4538 | G20: =+'REGISTRO 2- lote 10'!$H$18 -> 320 | H20: =+G20*1000/F20 -> 70.515646 | I20: =+I19+H20 -> 512.11732 | J20: =+'REGISTRO 2- lote 10'!U18 -> 455 | K20: =+J20-J13 -> 262 | L20: =+(J20-$J$6)/C20 -> 29.357143 | M20: =+I20/J20 -> 1.1255326 | N20: 380-390 | O20: =+O19+1 -> 14 | P20: =+'REGISTRO 2- lote 10'!$H$82 -> 9 | R20: =+R19-P20-Q20 -> 4996 | S20: =+'REGISTRO 2- lote 10'!$H$69 -> 320 | T20: =+S20*1000/R20 -> 64.051241 | U20: =+U19+T20 -> 489.112 | V20: =+'REGISTRO 2- lote 10'!U69 -> 445 | W20: =+V20-V13 -> 255 | X20: =+(V20-$J$6)/O20 -> 28.642857 | Y20: =+U20/V20 -> 1.0991281 | Z20: 375-380
A21: =+A20+1 -> 45795 | B21: Semana 3 | C21: =+C20+1 -> 15 | D21: =+'REGISTRO 2- lote 10'!$B$32 -> 3 | F21: =+F20-D21-E21 -> 4535 | G21: =+'REGISTRO 2- lote 10'!$B$19 -> 320 | H21: =+G21*1000/F21 -> 70.562293 | I21: =+I20+H21 -> 582.67961 | O21: =+O20+1 -> 15 | P21: =+'REGISTRO 2- lote 10'!$B$83 -> 3 | R21: =+R20-P21-Q21 -> 4993 | S21: =+'REGISTRO 2- lote 10'!$B$70 -> 320 | T21: =+S21*1000/R21 -> 64.089726 | U21: =+U20+T21 -> 553.20172
A22: =+A21+1 -> 45796 | C22: =+C21+1 -> 16 | D22: =+'REGISTRO 2- lote 10'!$C$32 -> 2 | F22: =+F21-D22-E22 -> 4533 | G22: =+'REGISTRO 2- lote 10'!$C$19 -> 320 | H22: =+G22*1000/F22 -> 70.593426 | I22: =+I21+H22 -> 653.27304 | O22: =+O21+1 -> 16 | P22: =+'REGISTRO 2- lote 10'!$C$83 -> 2 | R22: =+R21-P22-Q22 -> 4991 | S22: =+'REGISTRO 2- lote 10'!$C$70 -> 360 | T22: =+S22*1000/R22 -> 72.129834 | U22: =+U21+T22 -> 625.33156
A23: =+A22+1 -> 45797 | C23: =+C22+1 -> 17 | D23: =+'REGISTRO 2- lote 10'!$D$32 -> 3 | F23: =+F22-D23-E23 -> 4530 | G23: =+'REGISTRO 2- lote 10'!$D$19 -> 360 | H23: =+G23*1000/F23 -> 79.470199 | I23: =+I22+H23 -> 732.74324 | O23: =+O22+1 -> 17 | P23: =+'REGISTRO 2- lote 10'!$D$83 -> 4 | R23: =+R22-P23-Q23 -> 4987 | S23: =+'REGISTRO 2- lote 10'!$D$70 -> 400 | T23: =+S23*1000/R23 -> 80.208542 | U23: =+U22+T23 -> 705.5401
A24: =+A23+1 -> 45798 | C24: =+C23+1 -> 18 | D24: =+'REGISTRO 2- lote 10'!$E$32 -> 1 | F24: =+F23-D24-E24 -> 4529 | G24: =+'REGISTRO 2- lote 10'!$E$19 -> 360 | H24: =+G24*1000/F24 -> 79.487746 | I24: =+I23+H24 -> 812.23098 | O24: =+O23+1 -> 18 | P24: =+'REGISTRO 2- lote 10'!$E$83 -> 5 | R24: =+R23-P24-Q24 -> 4982 | S24: =+'REGISTRO 2- lote 10'!$E$70 -> 400 | T24: =+S24*1000/R24 -> 80.289041 | U24: =+U23+T24 -> 785.82914
A25: =+A24+1 -> 45799 | C25: =+C24+1 -> 19 | D25: =+'REGISTRO 2- lote 10'!$F$32 -> 4 | F25: =+F24-D25-E25 -> 4525 | G25: =+'REGISTRO 2- lote 10'!$F$19 -> 400 | H25: =+G25*1000/F25 -> 88.39779 | I25: =+I24+H25 -> 900.62877 | O25: =+O24+1 -> 19 | P25: =+'REGISTRO 2- lote 10'!$F$83 -> 3 | R25: =+R24-P25-Q25 -> 4979 | S25: =+'REGISTRO 2- lote 10'!$F$70 -> 400 | T25: =+S25*1000/R25 -> 80.337417 | U25: =+U24+T25 -> 866.16656
A26: =+A25+1 -> 45800 | C26: =+C25+1 -> 20 | D26: =+'REGISTRO 2- lote 10'!$G$32 -> 3 | F26: =+F25-D26-E26 -> 4522 | G26: =+'REGISTRO 2- lote 10'!$G$19 -> 440 | H26: =+G26*1000/F26 -> 97.302079 | I26: =+I25+H26 -> 997.93085 | O26: =+O25+1 -> 20 | P26: =+'REGISTRO 2- lote 10'!$G$83 -> 2 | R26: =+R25-P26-Q26 -> 4977 | S26: =+'REGISTRO 2- lote 10'!$G$70 -> 440 | T26: =+S26*1000/R26 -> 88.406671 | U26: =+U25+T26 -> 954.57323
A27: =+A26+1 -> 45801 | C27: =+C26+1 -> 21 | D27: =+'REGISTRO 2- lote 10'!$H$32 -> 3 | F27: =+F26-D27-E27 -> 4519 | G27: =+'REGISTRO 2- lote 10'!$H$19 -> 480 | H27: =+G27*1000/F27 -> 106.21819 | I27: =+I26+H27 -> 1104.149 | J27: =+'REGISTRO 2- lote 10'!U19 -> 880 | K27: =+J27-J20 -> 425 | L27: =+(J27-$J$6)/C27 -> 39.809524 | M27: =+I27/J27 -> 1.2547148 | N27: 730-780 | O27: =+O26+1 -> 21 | P27: =+'REGISTRO 2- lote 10'!$H$83 -> 4 | R27: =+R26-P27-Q27 -> 4973 | S27: =+'REGISTRO 2- lote 10'!$H$70 -> 440 | T27: =+S27*1000/R27 -> 88.47778 | U27: =+U26+T27 -> 1043.051 | V27: =+'REGISTRO 2- lote 10'!U70 -> 850 | W27: =+V27-V20 -> 405 | X27: =+(V27-$J$6)/O27 -> 38.380952 | Y27: =+U27/V27 -> 1.2271188 | Z27: 680-760
A28: =+A27+1 -> 45802 | B28: Semana 4 | C28: =+C27+1 -> 22 | D28: =+'REGISTRO 2- lote 10'!$B$33 -> 2 | F28: =+F27-D28-E28 -> 4517 | G28: =+'REGISTRO 2- lote 10'!$B$20 -> 480 | H28: =+G28*1000/F28 -> 106.26522 | I28: =+I27+H28 -> 1210.4143 | O28: =+O27+1 -> 22 | P28: =+'REGISTRO 2- lote 10'!$B$84 -> 3 | R28: =+R27-P28-Q28 -> 4970 | S28: =+'REGISTRO 2- lote 10'!$B$71 -> 440 | T28: =+S28*1000/R28 -> 88.531187 | U28: =+U27+T28 -> 1131.5822
A29: =+A28+1 -> 45803 | C29: =+C28+1 -> 23 | D29: =+'REGISTRO 2- lote 10'!$C$33 -> 1 | F29: =+F28-D29-E29 -> 4516 | G29: =+'REGISTRO 2- lote 10'!$C$20 -> 480 | H29: =+G29*1000/F29 -> 106.28875 | I29: =+I28+H29 -> 1316.703 | O29: =+O28+1 -> 23 | P29: =+'REGISTRO 2- lote 10'!$C$84 -> 3 | R29: =+R28-P29-Q29 -> 4967 | S29: =+'REGISTRO 2- lote 10'!$C$71 -> 480 | T29: =+S29*1000/R29 -> 96.63781 | U29: =+U28+T29 -> 1228.22
A30: =+A29+1 -> 45804 | C30: =+C29+1 -> 24 | D30: =+'REGISTRO 2- lote 10'!$D$33 -> 3 | F30: =+F29-D30-E30 -> 4513 | G30: =+'REGISTRO 2- lote 10'!$D$20 -> 520 | H30: =+G30*1000/F30 -> 115.22269 | I30: =+I29+H30 -> 1431.9257 | O30: =+O29+1 -> 24 | P30: =+'REGISTRO 2- lote 10'!$D$84 -> 6 | R30: =+R29-P30-Q30 -> 4961 | S30: =+'REGISTRO 2- lote 10'!$D$71 -> 520 | T30: =+S30*1000/R30 -> 104.81758 | U30: =+U29+T30 -> 1333.0376
A31: =+A30+1 -> 45805 | C31: =+C30+1 -> 25 | D31: =+'REGISTRO 2- lote 10'!$E$33 -> 2 | F31: =+F30-D31-E31 -> 4511 | G31: =+'REGISTRO 2- lote 10'!$E$20 -> 560 | H31: =+G31*1000/F31 -> 124.14099 | I31: =+I30+H31 -> 1556.0667 | O31: =+O30+1 -> 25 | P31: =+'REGISTRO 2- lote 10'!$E$84 -> 4 | R31: =+R30-P31-Q31 -> 4957 | S31: =+'REGISTRO 2- lote 10'!$E$71 -> 600 | T31: =+S31*1000/R31 -> 121.04095 | U31: =+U30+T31 -> 1454.0785
A32: =+A31+1 -> 45806 | C32: =+C31+1 -> 26 | D32: =+'REGISTRO 2- lote 10'!$F$33 -> 4 | F32: =+F31-D32-E32 -> 4507 | G32: =+'REGISTRO 2- lote 10'!$F$20 -> 600 | H32: =+G32*1000/F32 -> 133.12625 | I32: =+I31+H32 -> 1689.1929 | O32: =+O31+1 -> 26 | P32: =+'REGISTRO 2- lote 10'!$F$84 -> 6 | R32: =+R31-P32-Q32 -> 4951 | S32: =+'REGISTRO 2- lote 10'!$F$71 -> 640 | T32: =+S32*1000/R32 -> 129.26681 | U32: =+U31+T32 -> 1583.3453
A33: =+A32+1 -> 45807 | C33: =+C32+1 -> 27 | D33: =+'REGISTRO 2- lote 10'!$G$33 -> 3 | F33: =+F32-D33-E33 -> 4504 | G33: =+'REGISTRO 2- lote 10'!$G$20 -> 640 | H33: =+G33*1000/F33 -> 142.09591 | I33: =+I32+H33 -> 1831.2889 | O33: =+O32+1 -> 27 | P33: =+'REGISTRO 2- lote 10'!$G$84 -> 5 | R33: =+R32-P33-Q33 -> 4946 | S33: =+'REGISTRO 2- lote 10'!$G$71 -> 680 | T33: =+S33*1000/R33 -> 137.48484 | U33: =+U32+T33 -> 1720.8302
A34: =+A33+1 -> 45808 | C34: =+C33+1 -> 28 | D34: =+'REGISTRO 2- lote 10'!$H$33 -> 6 | F34: =+F33-D34-E34 -> 4498 | G34: =+'REGISTRO 2- lote 10'!$H$20 -> 640 | H34: =+G34*1000/F34 -> 142.28546 | I34: =+I33+H34 -> 1973.5743 | J34: =+'REGISTRO 2- lote 10'!U20 -> 1450 | K34: =+J34-J27 -> 570 | L34: =+(J34-$J$6)/C34 -> 50.214286 | M34: =+I34/J34 -> 1.3610857 | N34: 1210-1350 | O34: =+O33+1 -> 28 | P34: =+'REGISTRO 2- lote 10'!$H$84 -> 4 | R34: =+R33-P34-Q34 -> 4942 | S34: =+'REGISTRO 2- lote 10'!$H$71 -> 720 | T34: =+S34*1000/R34 -> 145.69 | U34: =+U33+T34 -> 1866.5202 | V34: =+'REGISTRO 2- lote 10'!U71 -> 1400 | W34: =+V34-V27 -> 550 | X34: =+(V34-$J$6)/O34 -> 48.428571 | Y34: =+U34/V34 -> 1.3332287 | Z34: 1150-1320
A35: =+A34+1 -> 45809 | B35: Semana 5 | C35: =+C34+1 -> 29 | D35: =+'REGISTRO 2- lote 10'!$B$34 -> 4 | F35: =+F34-D35-E35 -> 4494 | G35: =+'REGISTRO 2- lote 10'!$B$21 -> 640 | H35: =+G35*1000/F35 -> 142.41211 | I35: =+I34+H35 -> 2115.9864 | O35: =+O34+1 -> 29 | P35: =+'REGISTRO 2- lote 10'!$B$85 -> 2 | R35: =+R34-P35-Q35 -> 4940 | S35: =+'REGISTRO 2- lote 10'!$B$72 -> 680 | T35: =+S35*1000/R35 -> 137.65182 | U35: =+U34+T35 -> 2004.172
A36: =+A35+1 -> 45810 | C36: =+C35+1 -> 30 | D36: =+'REGISTRO 2- lote 10'!$C$34 -> 4 | F36: =+F35-D36-E36 -> 4490 | G36: =+'REGISTRO 2- lote 10'!$C$21 -> 640 | H36: =+G36*1000/F36 -> 142.53898 | I36: =+I35+H36 -> 2258.5254 | O36: =+O35+1 -> 30 | P36: =+'REGISTRO 2- lote 10'!$C$85 -> 3 | R36: =+R35-P36-Q36 -> 4937 | S36: =+'REGISTRO 2- lote 10'!$C$72 -> 680 | T36: =+S36*1000/R36 -> 137.73547 | U36: =+U35+T36 -> 2141.9075
A37: =+A36+1 -> 45811 | C37: =+C36+1 -> 31 | D37: =+'REGISTRO 2- lote 10'!$D$34 -> 6 | F37: =+F36-D37-E37 -> 4484 | G37: =+'REGISTRO 2- lote 10'!$D$21 -> 680 | H37: =+G37*1000/F37 -> 151.65031 | I37: =+I36+H37 -> 2410.1757 | O37: =+O36+1 -> 31 | P37: =+'REGISTRO 2- lote 10'!$D$85 -> 1 | R37: =+R36-P37-Q37 -> 4936 | S37: =+'REGISTRO 2- lote 10'!$D$72 -> 680 | T37: =+S37*1000/R37 -> 137.76337 | U37: =+U36+T37 -> 2279.6709
A38: =+A37+1 -> 45812 | C38: =+C37+1 -> 32 | D38: =+'REGISTRO 2- lote 10'!$E$34 -> 3 | F38: =+F37-D38-E38 -> 4481 | G38: =+'REGISTRO 2- lote 10'!$E$21 -> 680 | H38: =+G38*1000/F38 -> 151.75184 | I38: =+I37+H38 -> 2561.9275 | O38: =+O37+1 -> 32 | P38: =+'REGISTRO 2- lote 10'!$E$85 -> 4 | R38: =+R37-P38-Q38 -> 4932 | S38: =+'REGISTRO 2- lote 10'!$E$72 -> 720 | T38: =+S38*1000/R38 -> 145.9854 | U38: =+U37+T38 -> 2425.6563
A39: =+A38+1 -> 45813 | C39: =+C38+1 -> 33 | D39: =+'REGISTRO 2- lote 10'!$F$34 -> 4 | F39: =+F38-D39-E39 -> 4477 | G39: =+'REGISTRO 2- lote 10'!$F$21 -> 720 | H39: =+G39*1000/F39 -> 160.82198 | I39: =+I38+H39 -> 2722.7495 | O39: =+O38+1 -> 33 | P39: =+'REGISTRO 2- lote 10'!$F$85 -> 2 | R39: =+R38-P39-Q39 -> 4930 | S39: =+'REGISTRO 2- lote 10'!$F$72 -> 720 | T39: =+S39*1000/R39 -> 146.04462 | U39: =+U38+T39 -> 2571.7009
A40: =+A39+1 -> 45814 | C40: =+C39+1 -> 34 | D40: =+'REGISTRO 2- lote 10'!$G$34 -> 7 | F40: =+F39-D40-E40 -> 4470 | G40: =+'REGISTRO 2- lote 10'!$G$21 -> 720 | H40: =+G40*1000/F40 -> 161.07383 | I40: =+I39+H40 -> 2883.8234 | O40: =+O39+1 -> 34 | P40: =+'REGISTRO 2- lote 10'!$G$85 -> 5 | R40: =+R39-P40-Q40 -> 4925 | S40: =+'REGISTRO 2- lote 10'!$G$72 -> 720 | T40: =+S40*1000/R40 -> 146.19289 | U40: =+U39+T40 -> 2717.8938
...

Sheet REGISTRO TOTAL
B1: AVICOLA SAN LORENZO
B2: GRANJA : | E2: SAN LORENZO
B3: RESPONSABLE : | E3: =+'REGISTRO 1- lote 9'!E3 -> 0 | O3: MACHO
B5: GALPON | D5: LOTE | G5: INCUBADORA | K5: CANTIDAD INICIAL | O5: PESO PROMEDIO INIC.
B6: =+'REGISTRO 1- lote 9'!B6:C6 -> T1 | D6: =+'REGISTRO 1- lote 9'!D6:E6 -> 49 | G6: =+'REGISTRO 1- lote 9'!G6:J6 -> FINAVES | K6: =+'REGISTRO 2- lote 10'!K6:N6+'REGISTRO 1- lote 9'!K6:N6 -> 11238 | O6: =+('REGISTRO 1- lote 9'!O6:R6+'REGISTRO 2- lote 10'!O6:R6)/2 -> 44
B8: FECHA INICIO | G8: =+'REGISTRO 2- lote 10'!G8:J8 -> 45780 | L8: DIAS DE ENGORDE: | P8: =(G9-G8)+1 -> 52
B9: FECHA TERMINACION | G9: =+PESAS!B19 -> 45831 | L9: DIAS PROMEDIO
B11: POLLOS VENDIDOS | G11: =+PESAS!M39 -> 10553 | Z11: conversion: kilos concentrado/ kilos en pie
B12: PESO TOTAL FINAL | G12: =+PESAS!M40 -> 32404.24 | L12: CONSUMO TOTAL DEL LOTE | Q12: =+T25 -> 5.2206857 | Z12: se necesita xxx kilos concentrado para producir 1 kilo de pollo en pie
Z13: Entre mas bajo mejor
I14: TOTAL CONSUMO | Q14: CONSUMO POR AVE | U14: PESO
A15: KILOS CONSUMIDOS | I15: SEMANAL | M15: ACUMULADO | Q15: (Gramos) | T15: CONSUMO | U15: GRAMOS | V15: gramos | Z15: BULTOS CONSUMIDOS
A16: S/D | B16: =+'REGISTRO 2- lote 10'!B16 -> S | C16: =+'REGISTRO 2- lote 10'!C16 -> D | D16: =+'REGISTRO 2- lote 10'!D16 -> L | E16: =+'REGISTRO 2- lote 10'!E16 -> M | F16: =+'REGISTRO 2- lote 10'!F16 -> M | G16: =+'REGISTRO 2- lote 10'!G16 -> J | H16: =+'REGISTRO 2- lote 10'!H16 -> V | I16: Bultos | K16: Kilos | M16: Bultos | O16: Kilos | Q16: Diario | R16: Sem. | S16: Acumul. | T16: KL. | U16: PROMEDIO | V16: Ganancia dia | W16: Conversion | X16: VPI | Z16: S/D | AA16: =+B16 -> S | AB16: =+C16 -> D | AC16: =+D16 -> L | AD16: =+E16 -> M | AE16: =+F16 -> M | AF16: =+G16 -> J | AG16: =+H16 -> V | AH16: TOTAL
A17: 1 | B17: =+'REGISTRO 2- lote 10'!B17+'REGISTRO 1- lote 9'!B17 -> 160 | C17: =+'REGISTRO 2- lote 10'!C17+'REGISTRO 1- lote 9'!C17 -> 160 | D17: =+'REGISTRO 2- lote 10'!D17+'REGISTRO 1- lote 9'!D17 -> 200 | E17: =+'REGISTRO 2- lote 10'!E17+'REGISTRO 1- lote 9'!E17 -> 260 | F17: =+'REGISTRO 2- lote 10'!F17+'REGISTRO 1- lote 9'!F17 -> 280 | G17: =+'REGISTRO 2- lote 10'!G17+'REGISTRO 1- lote 9'!G17 -> 320 | H17: =+'REGISTRO 2- lote 10'!H17+'REGISTRO 1- lote 9'!H17 -> 400 | I17: =+K17/40 -> 44.5 | K17: =SUM(B17:H17) -> 1780 | M17: =+I17 -> 44.5 | O17: =+K17 -> 1780 | Q17: =+R17/7 -> 23.066556 | R17: =+K17*1000/S30 -> 161.46589 | S17: =+R17 -> 161.46589 | T17: =+O17/S30 -> 0.16146589 | U17: =+('REGISTRO 1- lote 9'!U17+'REGISTRO 2- lote 10'!U17)/2 -> 194 | V17: =(U17-O6)/7 -> 21.428571 | W17: =+O17/(S30*(U17/1000)) -> 0.83229842 | X17: =+U17/O6 -> 4.4090909 | Z17: 1 | AA17: =+'REGISTRO 2- lote 10'!AA17+'REGISTRO 1- lote 9'!AA17 -> 4 | AB17: =+'REGISTRO 2- lote 10'!AB17+'REGISTRO 1- lote 9'!AB17 -> 4 | AC17: =+'REGISTRO 2- lote 10'!AC17+'REGISTRO 1- lote 9'!AC17 -> 5 | AD17: =+'REGISTRO 2- lote 10'!AD17+'REGISTRO 1- lote 9'!AD17 -> 6.5 | AE17: =+'REGISTRO 2- lote 10'!AE17+'REGISTRO 1- lote 9'!AE17 -> 7 | AF17: =+'REGISTRO 2- lote 10'!AF17+'REGISTRO 1- lote 9'!AF17 -> 8 | AG17: =+'REGISTRO 2- lote 10'!AG17+'REGISTRO 1- lote 9'!AG17 -> 10 | AH17: =+SUM(AA17:AG17) -> 44.5
